Workbook

Sheet Main
A1: ID | B1: InterGroup | C1: InterGroup2 | D1: Assessment | E1: Date | F1: Age | G1: Sex | H1: Height (cm) | I1: Height (ft) | J1: Height (inch) | K1: Weight (kg) | L1: Weight (lbs) | M1: Steps | N1: METs | O1: VMCPM | P1: A1CPM | Q1: AATapa | R1: AATaps | S1: AATava | T1: AATavs | U1: WHOQOL | V1: Affect | W1: Instrum | X1: PES | Y1: 6MWT | Z1: Grip (KG*N) | AB1: notes
A2: J001 | B2: 1 | C2: 1 | D2: 1 | E2: 250403 | F2: 75 | G2: F | H2: 165 | I2: =INT(ROUND(H2 / 2.54 *8, 0) / 96) -> 5 | J2: =ROUND((H2 / 2.54 - I2 * 12) * 8,0) / 8 -> 5 | K2: 65 | L2: =K2*2.2 -> 143 | M2: 3665.5 | N2: 1.056 | O2: 420.9 | P2: 186.2 | Q2: -622.56548 | R2: -301.35714 | S2: -298.24547 | T2: -119.49547 | U2: 119 | V2: 14 | W2: 14 | X2: 2.5 | Y2: 435 | Z2: 27
A3: J001 | B3: 1 | C3: 1 | D3: 2 | E3: 250505 | M3: 3926 | N3: 1.048 | O3: 418.3 | P3: 178.9 | Q3: -170.14015 | R3: -4.7651515 | S3: -28.009058 | T3: 1.8478261 | U3: 120 | V3: 12 | W3: 12 | X3: 2.75 | Y3: 495 | Z3: 20
A4: J001 | B4: 1 | C4: 1 | D4: 3 | E4: 250603 | M4: 3620 | N4: 1.052 | O4: 432.6 | P4: 181.9 | Q4: -44.576087 | R4: 75.833333 | S4: -98.458333 | T4: 168.07971 | U4: 109 | V4: 12 | W4: 12 | X4: 1.5 | Y4: 457.5 | Z4: 24
A5: J002 | B5: 0 | C5: 1 | D5: 1 | E5: 250414 | F5: 70 | G5: F | H5: 171 | I5: =INT(ROUND(H5 / 2.54 *8, 0) / 96) -> 5 | J5: =ROUND((H5 / 2.54 - I5 * 12) * 8,0) / 8 -> 7.375 | K5: 55.2 | L5: =K5*2.2 -> 121.44 | M5: 8572.1429 | N5: 1.179 | O5: 582.9 | P5: 329.7 | Q5: 49.072464 | R5: 54.036232 | S5: 88.944746 | T5: 833.55542 | U5: 129 | V5: 14 | W5: 14 | X5: 2 | Y5: 532.5 | Z5: 30
A6: J002 | B6: 0 | C6: 1 | D6: 2 | E6: 250602 | M6: 8715 | N6: 1.153 | O6: 661.8 | P6: 344.5 | Q6: 151.84524 | R6: 659.17857 | S6: 48.446558 | T6: 171.97373 | U6: 127 | V6: 14 | W6: 14 | X6: 4 | Y6: 540 | Z6: 29
A7: J002 | B7: 0 | C7: 1 | D7: 3 | E7: 250707 | M7: 5360.5714 | N7: 1.074 | O7: 502.7 | P7: 226.1 | Q7: 60.306159 | R7: 112.1558 | S7: -54.602026 | T7: 226.7654 | U7: 130 | V7: 14 | W7: 14 | X7: 4 | Y7: 525 | Z7: 35
A8: J003 | B8: 1 | C8: 11 | D8: 1 | E8: 250414 | F8: 68 | G8: M | H8: 169 | I8: =INT(ROUND(H8 / 2.54 *8, 0) / 96) -> 5 | J8: =ROUND((H8 / 2.54 - I8 * 12) * 8,0) / 8 -> 6.5 | K8: 54.8 | L8: =K8*2.2 -> 120.56 | M8: 10237.857 | N8: 1.187 | O8: 680.1 | P8: 362.7 | Q8: -87.643939 | R8: 504.96439 | S8: 365.14427 | T8: -32.431818 | U8: 118 | V8: 14 | W8: 14 | X8: 2.75 | Y8: 510 | Z8: 48
A9: J003 | B9: 1 | C9: 11 | D9: 2 | E9: 250602 | M9: 8895.2857 | N9: 1.117 | O9: 593.4 | P9: 292.8 | Q9: -71.471218 | R9: 456.01985 | S9: 394.69565 | T9: 52.655797 | U9: 122 | V9: 13 | W9: 14 | X9: 2.75 | Y9: 570 | Z9: 44
A10: J003 | B10: 1 | C10: 11 | D10: 3 | E10: 250707 | M10: 6312.5714 | N10: 1.071 | O10: 547.1 | P10: 227.8 | Q10: -5.1166008 | R10: 333.78261 | S10: 98.457016 | T10: -55.405303 | U10: 125 | V10: 12 | W10: 14 | X10: 3 | Y10: 555 | Z10: 48
A11: J004 | B11: 0 | C11: 11 | D11: 1 | E11: 250416 | F11: 65 | G11: F | H11: 159 | I11: =INT(ROUND(H11 / 2.54 *8, 0) / 96) -> 5 | J11: =ROUND((H11 / 2.54 - I11 * 12) * 8,0) / 8 -> 2.625 | K11: 51.7 | L11: =K11*2.2 -> 113.74 | M11: 8501.1667 | N11: 1.134 | O11: 858.4 | P11: 380.2 | Q11: 158.60054 | R11: -90.881341 | S11: -331.02083 | T11: 893.75272 | U11: 107 | V11: 10 | W11: 12 | X11: 2 | Y11: 412.5 | Z11: 36
A12: J004 | B12: 0 | C12: 11 | D12: 2 | E12: 250514 | M12: 10406.714 | N12: 1.18 | O12: 967 | P12: 452 | Q12: 156.52536 | R12: -166.6413 | S12: -269.66667 | T12: -93.625 | U12: 108 | V12: 10 | W12: 12 | X12: 2 | Y12: 457.5 | Z12: 34
A13: J004 | B13: 0 | C13: 11 | D13: 3 | E13: 250617 | M13: 7257.7143 | N13: 1.097 | O13: 844.9 | P13: 326.9 | Q13: 194.34692 | R13: 24.160326 | S13: -11.9375 | T13: -20.770833 | U13: 106 | V13: 10 | W13: 12 | X13: 2 | Y13: 495 | Z13: 38
A14: J005 | B14: 1 | C14: 1 | D14: 1 | E14: 250430 | F14: 70 | G14: M | H14: 177 | I14: =INT(ROUND(H14 / 2.54 *8, 0) / 96) -> 5 | J14: =ROUND((H14 / 2.54 - I14 * 12) * 8,0) / 8 -> 9.625 | K14: 90.5 | L14: 199.6 | M14: 2794.6667 | N14: 1.016 | O14: 358.8 | P14: 106.5 | Q14: 124.39583 | R14: -10.229167 | S14: -127.17391 | T14: 326.49275 | U14: 112 | V14: 12 | W14: 14 | X14: 2.25 | Y14: 322.5 | Z14: 26
A15: J005 | B15: 1 | C15: 1 | D15: 2 | E15: 250523 | M15: 3704.2857 | N15: 1.011 | O15: 506.3 | P15: 129.3 | Q15: 99.729167 | R15: -61.395833 | S15: 78.826087 | T15: 205.52174 | U15: 115 | V15: 12 | W15: 13 | X15: 2 | Y15: 435 | Z15: 29
A16: J005 | B16: 1 | C16: 1 | D16: 3 | E16: 250715 | M16: 6651.125 | N16: 1.042 | O16: 713 | P16: 246.1 | Q16: 105.16667 | R16: 265.29167 | S16: 33.169384 | T16: 124.39764 | U16: 108 | V16: 10 | W16: 14 | X16: 1.25 | Y16: 405 | Z16: 27
A17: J006 | B17: 0 | C17: 1 | D17: 1 | E17: 250515 | F17: 79 | G17: M | H17: 177 | I17: =INT(ROUND(H17 / 2.54 *8, 0) / 96) -> 5 | J17: =ROUND((H17 / 2.54 - I17 * 12) * 8,0) / 8 -> 9.625 | K17: =L17/2.2 -> 99.090909 | L17: 218 | M17: 2131.3333 | N17: 1.014 | O17: 353.6 | P17: 99 | Q17: 161.79464 | R17: 607.90153 | S17: 661.03837 | T17: 207.61575 | U17: 100 | V17: 8 | W17: 12 | X17: 0.75 | Y17: 337.5 | Z17: 32
A18: J006 | B18: 0 | C18: 1 | D18: 2 | E18: 250714 | M18: 1378.75 | N18: 1.003 | O18: 276.1 | P18: 61.7 | Q18: 26.070393 | R18: 139.22981 | S18: 45.734091 | T18: 28.552273 | U18: 103 | V18: 11 | W18: 12 | X18: 0 | Y18: 337.5 | Z18: 32
A19: J006 | B19: 0 | C19: 1 | D19: 3 | E19: 250808 | M19: 1604.5714 | N19: 1.007 | O19: 226 | P19: 88 | Q19: 132.47875 | R19: -224.69697 | S19: 130.01812 | T19: 58.192029 | U19: 100 | V19: 10 | W19: 13 | X19: 0.25 | Y19: 367.5 | Z19: 32
A20: J007 | B20: 0 | C20: 11 | D20: 1 | E20: 250611 | F20: 72 | G20: F | H20: 162 | I20: =INT(ROUND(H20 / 2.54 *8, 0) / 96) -> 5 | J20: =ROUND((H20 / 2.54 - I20 * 12) * 8,0) / 8 -> 3.75 | K20: 66.3 | L20: 146.2 | M20: 7039.7143 | N20: 1.139 | O20: 587.2 | P20: 279.5 | Q20: 459.47101 | R20: 367.63768 | S20: 581.59058 | T20: 165.41667 | U20: 109 | V20: 10 | W20: 14 | X20: 0 | Y20: 435 | Z20: 23
A21: J007 | B21: 0 | C21: 11 | D21: 2 | E21: 250721 | M21: 8007.8571 | N21: 1.186 | O21: 646.8 | P21: 318.2 | Q21: 272.90314 | R21: 235.375 | S21: 62.742754 | T21: 161.97645 | U21: 114 | V21: 9 | W21: 12 | X21: 0.75 | Y21: 412.5 | Z21: 24
A22: J007 | B22: 0 | C22: 11 | D22: 3 | E22: 250808 | M22: 5277.4286 | N22: 1.161 | O22: 567 | P22: 273.8 | Q22: 24.125 | R22: 243.94102 | S22: 357.08144 | T22: 107.60417 | U22: 114 | V22: 10 | W22: 11 | X22: 0.5 | Y22: 427.5 | Z22: 22
A23: J008 | B23: 1 | C23: 11 | D23: 1 | E23: 250623 | F23: 61 | G23: F | H23: 143 | I23: =INT(ROUND(H23 / 2.54 *8, 0) / 96) -> 4 | J23: =ROUND((H23 / 2.54 - I23 * 12) * 8,0) / 8 -> 8.25 | K23: =L23/2.2 -> 84.090909 | L23: 185 | M23: 3490.625 | N23: 1.036 | O23: 516.6 | P23: 194.7 | Q23: 199.82609 | R23: 88.826087 | S23: 308.53895 | T23: 389.2346 | U23: 109 | V23: 9 | W23: 14 | X23: 1.5 | Y23: 382.5 | Z23: 23
A24: J008 | B24: 1 | C24: 11 | D24: 2 | E24: 250729 | M24: 2594 | N24: 1.02 | O24: 500.4 | P24: 167.2 | Q24: 90.371894 | R24: 158.52588 | S24: -77.341486 | T24: 81.491848 | U24: 117 | V24: 11 | W24: 14 | X24: 3.25 | Y24: 457.5 | Z24: 22
A25: J008 | B25: 1 | C25: 11 | D25: 3 | E25: 250819 | M25: 2787.8571 | N25: 1.033 | O25: 504.6 | P25: 192.8 | Q25: -644.44928 | R25: -438.44384 | S25: -156.19952 | T25: -127.50387 | U25: 105 | V25: 9 | W25: 12 | X25: 3.25 | Y25: 420 | Z25: 20
A26: J009 | B26: 1 | C26: 1 | D26: 1 | E26: 250703 | F26: 62 | G26: F | H26: 162 | I26: =INT(ROUND(H26 / 2.54 *8, 0) / 96) -> 5 | J26: =ROUND((H26 / 2.54 - I26 * 12) * 8,0) / 8 -> 3.75 | K26: =L26/2.2 -> 81.363636 | L26: 179 | M26: 9009.75 | N26: 1.234 | O26: 597.6 | P26: 326 | Q26: -229.14583 | R26: 69.5625 | S26: 23.184783 | T26: -63.981884 | U26: 104 | V26: 12 | W26: 13 | X26: 3.25 | Y26: 442.5 | Z26: 22
A27: J009 | B27: 1 | C27: 1 | D27: 2 | E27: 250807 | M27: 11848 | N27: 1.32 | O27: 731.5 | P27: 404.7 | Q27: 8.120471 | R27: 218.07699 | S27: 17.997283 | T27: -112.35054 | U27: 105 | V27: 12 | W27: 11 | X27: 3.25 | Y27: 532.5 | Z27: 28
A28: J009 | B28: 1 | C28: 1 | D28: 3 | E28: 250905 | M28: 7946.2222 | N28: 1.21 | O28: 613.4 | P28: 337.7 | Q28: 53.422101 | R28: 292.63043 | S28: 122.04167 | T28: 65.208333 | U28: 108 | V28: 12 | W28: 12 | X28: 4 | Y28: 457.5 | Z28: 29
A29: J010 | B29: 0 | C29: 11 | D29: 1 | E29: 250702 | F29: 64 | G29: M | H29: 172 | I29: =INT(ROUND(H29 / 2.54 *8, 0) / 96) -> 5 | J29: =ROUND((H29 / 2.54 - I29 * 12) * 8,0) / 8 -> 7.75 | K29: =L29/2.2 -> 85.909091 | L29: 189 | M29: 16352.143 | N29: 1.573 | O29: 939.8 | P29: 569.8 | Q29: 73.97192 | R29: 532.79603 | S29: 347.75543 | T29: 117.1721 | U29: 102 | V29: 12 | W29: 12 | X29: 2.75 | Y29: 517.5 | Z29: 32
A30: J010 | B30: 0 | C30: 11 | D30: 2 | E30: 250806 | M30: 24100.625 | N30: 1.833 | O30: 1154.3 | P30: 756.6 | Q30: 124.6721 | R30: 247.98758 | S30: 66.958333 | T30: -79.875 | U30: 104 | V30: 12 | W30: 14 | X30: 3 | Y30: 577.5 | Z30: 32
A31: J010 | B31: 0 | C31: 11 | D31: 3 | E31: 250905 | M31: 19023.875 | N31: 1.648 | O31: 973.6 | P31: 608.6 | Q31: 177.92029 | R31: 162.77717 | S31: 146.5 | T31: 179.375 | U31: 106 | V31: 12 | W31: 12 | X31: 3 | Y31: 585 | Z31: 36
A32: J011 | B32: 0 | C32: 1 | D32: 1 | E32: 250702 | F32: 69 | G32: F | H32: 162 | I32: =INT(ROUND(H32 / 2.54 *8, 0) / 96) -> 5 | J32: =ROUND((H32 / 2.54 - I32 * 12) * 8,0) / 8 -> 3.75 | K32: =L32/2.2 -> 83.181818 | L32: 183 | M32: 2918.6667 | N32: 1.042 | O32: 403.7 | P32: 139.5 | Q32: 108.97357 | R32: 144.83523 | S32: 165.64229 | T32: 268.05138 | U32: 76 | V32: 10 | W32: 14 | X32: 2 | Y32: 322.5 | Z32: 30
A33: J011 | B33: 0 | C33: 1 | D33: 2 | E33: 250807 | M33: 1506.1429 | N33: 1.02 | O33: 324.8 | P33: 99 | Q33: 283.44623 | R33: 339.94623 | S33: 96.971014 | T33: 314.05435 | U33: 75 | V33: 10 | W33: 14 | X33: 0.5 | Y33: 360 | Z33: 33
A34: J011 | B34: 0 | C34: 1 | D34: 3 | E34: 250902 | M34: 2106.8571 | N34: 1.054 | O34: 339.1 | P34: 129.6 | Q34: 183.46467 | R34: 176.21467 | S34: 64.771739 | T34: 111.35507 | U34: 81 | V34: 14 | W34: 14 | X34: 0 | Y34: 405 | Z34: 36
A35: J012 | B35: 1 | C35: 1 | D35: 1 | E35: 250714 | F35: 70 | G35: F | H35: 161 | I35: =INT(ROUND(H35 / 2.54 *8, 0) / 96) -> 5 | J35: =ROUND((H35 / 2.54 - I35 * 12) * 8,0) / 8 -> 3.375 | K35: =L35/2.2 -> 76.727273 | L35: 168.8 | M35: 2776.75 | N35: 1.017 | O35: 258.3 | P35: 81.4 | Q35: 77.156291 | R35: 593.91613 | S35: 456.03409 | T35: 174.81126 | U35: 64 | V35: 12 | W35: 13 | X35: 0 | Y35: 457.5 | Z35: 18
A36: J012 | B36: 1 | C36: 1 | D36: 2 | E36: 250731 | M36: 2862 | N36: 1.008 | O36: 211.1 | P36: 72.8 | Q36: -23.179924 | R36: -10.50947 | S36: -38.21558 | T36: -87.086957 | U36: 58 | V36: 4 | W36: 6 | X36: 0 | Y36: 405 | Z36: 16
A37: J012 | B37: 1 | C37: 1 | D37: 3 | E37: 250902 | M37: 3028 | N37: 1.022 | O37: 278.6 | P37: 114.2 | Q37: -234.91667 | R37: -410.25 | S37: 55.321558 | T37: -6.8125 | U37: 60 | V37: 6 | W37: 8 | X37: 1 | Y37: 412.5 | Z37: 22
A38: J013 | B38: 1 | C38: 11 | D38: 1 | E38: 250716 | F38: 66 | G38: F | H38: 163.5 | I38: =INT(ROUND(H38 / 2.54 *8, 0) / 96) -> 5 | J38: =ROUND((H38 / 2.54 - I38 * 12) * 8,0) / 8 -> 4.375 | K38: =L38/2.2 -> 76.363636 | L38: 168 | M38: 2980.1429 | N38: 1.02 | O38: 299.6 | P38: 130.1 | Q38: 181.82518 | R38: 1354.2299 | S38: 145.78714 | T38: 78.453804 | U38: 107 | V38: 8 | W38: 12 | X38: 1.25 | Y38: 375 | Z38: 22
A39: J013 | B39: 1 | C39: 11 | D39: 2 | E39: 250818 | M39: 1929.375 | N39: 1.007 | O39: 230.3 | P39: 87.4 | Q39: 16.347826 | R39: 231.55336 | S39: -113.53895 | T39: -64.980978 | U39: 107 | V39: 8 | W39: 12 | X39: 0.5 | Y39: 300 | Z39: 26
A40: J013 | B40: 1 | C40: 11 | D40: 3 | E40: 250917 | M40: 3637.625 | N40: 1.039 | O40: 343.5 | P40: 145.3 | Q40: -107.25 | R40: 221.35 | S40: 58.458333 | T40: 5.0416667 | U40: 110 | V40: 8 | W40: 14 | X40: 1.5 | Y40: 352.5 | Z40: 26
...

Sheet JOGGNGRT
A1: participants | B1: interGroup | C1: cwGroup | D1: sess1 | E1: sess2 | F1: sess3 | G1: sess4 | H1: sess5 | I1: sess6 | J1: sess7 | K1: sess8 | L1: sess9
A2: J001 | B2: 1 | C2: 1 | D2: 520.94229 | E2: 470.38487 | F2: 434.69877 | G2: nan | H2: nan | I2: nan | J2: nan | K2: nan | L2: nan
A3: J002 | B3: 0 | C3: 1 | D3: 494.49967 | E3: 464.79147 | F3: 474.94536 | G3: 456.01592 | H3: 454.42028 | I3: 425.7599 | J3: 425.5708 | K3: 414.96834 | L3: 397.98407
A4: J003 | B4: 1 | C4: 11 | D4: 454.5306 | E4: 385.45865 | F4: 413.12946 | G4: 423.5135 | H4: 400.32265 | I4: 393.70412 | J4: 395.40142 | K4: 385.85997 | L4: 393.93752
A5: J004 | B5: 0 | C5: 11 | D5: 517.85111 | E5: 505.45965 | F5: 496.57008 | G5: 488.80985 | H5: 497.89129 | I5: 505.63354 | J5: 488.52635 | K5: 481.00716 | L5: 495.16502
A6: J005 | B6: 1 | C6: 1 | D6: 506.23798 | E6: 514.83269 | F6: 541.61211 | G6: 523.95485 | H6: 539.7862 | I6: 541.74378 | J6: nan | K6: nan | L6: nan
A7: J006 | B7: 0 | C7: 1 | D7: 551.06558 | E7: 517.97335 | F7: 520.20994 | G7: 517.60516 | H7: 512.40785 | I7: 494.40108 | J7: 488.71587 | K7: 481.23252 | L7: 486.04719
A8: J007 | B8: 0 | C8: 11 | D8: 518.1789 | E8: 437.40122 | F8: 413.1288 | G8: 419.20568 | H8: 389.54431 | I8: 394.55408 | J8: 397.44485 | K8: 378.08115 | L8: 377.0858
A9: J008 | B9: 1 | C9: 11 | D9: 499.80134 | E9: 479.62326 | F9: 473.04129 | G9: 459.35308 | H9: 454.99852 | I9: 447.49151 | J9: 451.63139 | K9: 443.76914 | L9: 434.73876
A10: J009 | B10: 1 | C10: 1 | D10: 471.49357 | E10: 425.0117 | F10: 406.46904 | G10: 423.215 | H10: 396.90389 | I10: 407.00259 | J10: 409.12899 | K10: 400.738 | L10: 409.68968
A11: J010 | B11: 0 | C11: 11 | D11: 483.15825 | E11: 471.58097 | F11: 470.25922 | G11: 465.79091 | H11: 431.07994 | I11: 425.72733 | J11: 443.69631 | K11: 434.49102 | L11: 439.89829
A12: J011 | B12: 0 | C12: 1 | D12: 513.24505 | E12: 480.59949 | F12: 468.81004 | G12: 460.48336 | H12: 454.31161 | I12: 456.4544 | J12: 471.9643 | K12: 462.85629 | L12: 439.40713
A13: J012 | B13: 1 | C13: 1 | D13: 487.25106 | E13: 462.63625 | F13: 452.34947 | G13: 446.21426 | H13: nan | I13: nan | J13: nan | K13: nan | L13: nan
A14: J013 | B14: 1 | C14: 11 | D14: 486.26196 | E14: 476.96705 | F14: 467.00749 | G14: 484.17825 | H14: 444.69389 | I14: 493.95292 | J14: 476.08783 | K14: 478.4283 | L14: 481.03899
A15: J014 | B15: 0 | C15: 1 | D15: 509.43834 | E15: 447.1709 | F15: 413.00025 | G15: 394.39956 | H15: 385.64921 | I15: 408.32264 | J15: 393.4966 | K15: 394.19336 | L15: 404.14715
A17: 494.49967 | B17: 520.94229 | D17: =AVERAGEIF(B2:B15,0,D2:D15) -> 512.49099 | L17: 397.98407 | M17: 393.93752 | O17: =AVERAGE(L17:L23) -> 434.24781
A18: 517.85111 | B18: 454.5306 | D18: =STDEV(A17:A23) -> 21.381715 | L18: 495.16502 | M18: 434.73876 | O18: =STDEV(L17:L23) -> 44.611719
A19: 551.06558 | B19: 506.23798 | D19: =AVERAGEIF(B2:B15,1,D2:D15) -> 489.50269 | L19: 486.04719 | M19: 409.68968 | O19: =AVERAGE(M17:M23) -> 429.85124
A20: 518.1789 | B20: 499.80134 | D20: =STDEV(B17:B23) -> 22.126639 | L20: 377.0858 | M20: 481.03899 | O20: =STDEV(M17:M20) -> 38.036637
A21: 483.15825 | B21: 471.49357 | L21: 439.89829
A22: 513.24505 | B22: 487.25106 | L22: 439.40713
A23: 509.43834 | B23: 486.26196 | L23: 404.14715

Sheet JOGGNGError
A1: participants | B1: interGroup | C1: cwGroup | D1: sess1 | E1: sess2 | F1: sess3 | G1: sess4 | H1: sess5 | I1: sess6 | J1: sess7 | K1: sess8 | L1: sess9
A2: J001 | B2: 1 | C2: 1 | D2: 3.8888889 | E2: 1.8055556 | F2: 1.9444444 | G2: nan | H2: nan | I2: nan | J2: nan | K2: nan | L2: nan
A3: J002 | B3: 0 | C3: 1 | D3: 4.3055556 | E3: 4.5833333 | F3: 1.6666667 | G3: 2.9166667 | H3: 2.2222222 | I3: 1.5277778 | J3: 2.3611111 | K3: 1.6666667 | L3: 2.3611111
A4: J003 | B4: 1 | C4: 11 | D4: 1.5277778 | E4: 5 | F4: 2.6388889 | G4: 2.3611111 | H4: 2.7777778 | I4: 3.0555556 | J4: 2.9166667 | K4: 2.3611111 | L4: 2.5
A5: J004 | B5: 0 | C5: 11 | D5: 3.1944444 | E5: 0.69444444 | F5: 0.83333333 | G5: 1.5277778 | H5: 0.83333333 | I5: 0.97222222 | J5: 0.83333333 | K5: 0.83333333 | L5: 0.41666667
A6: J005 | B6: 1 | C6: 1 | D6: 5 | E6: 1.8055556 | F6: 2.9166667 | G6: 1.25 | H6: 1.6666667 | I6: 0.69444444 | J6: nan | K6: nan | L6: nan
A7: J006 | B7: 0 | C7: 1 | D7: 13.194444 | E7: 3.1944444 | F7: 3.1944444 | G7: 2.2222222 | H7: 2.0833333 | I7: 2.0833333 | J7: 2.7777778 | K7: 2.0833333 | L7: 2.3611111
A8: J007 | B8: 0 | C8: 11 | D8: 2.5 | E8: 0.55555556 | F8: 0.41666667 | G8: 0.41666667 | H8: 0.41666667 | I8: 1.1111111 | J8: 0.55555556 | K8: 0.55555556 | L8: 0.69444444
A9: J008 | B9: 1 | C9: 11 | D9: 10.416667 | E9: 3.3333333 | F9: 1.3888889 | G9: 1.6666667 | H9: 1.25 | I9: 0.55555556 | J9: 0.97222222 | K9: 2.3611111 | L9: 1.1111111
A10: J009 | B10: 1 | C10: 1 | D10: 7.5 | E10: 4.7222222 | F10: 5 | G10: 2.6388889 | H10: 3.3333333 | I10: 3.4722222 | J10: 2.9166667 | K10: 3.0555556 | L10: 3.6111111
A11: J010 | B11: 0 | C11: 11 | D11: 2.6388889 | E11: 0.97222222 | F11: 0.83333333 | G11: 0.69444444 | H11: 2.3611111 | I11: 1.5277778 | J11: 1.1111111 | K11: 1.25 | L11: 0.83333333
A12: J011 | B12: 0 | C12: 1 | D12: 4.0277778 | E12: 1.5277778 | F12: 1.5277778 | G12: 1.5277778 | H12: 1.6666667 | I12: 1.3888889 | J12: 0.83333333 | K12: 1.1111111 | L12: 1.3888889
A13: J012 | B13: 1 | C13: 1 | D13: 7.0833333 | E13: 3.0555556 | F13: 1.8055556 | G13: 1.25 | H13: nan | I13: nan | J13: nan | K13: nan | L13: nan
A14: J013 | B14: 1 | C14: 11 | D14: 2.2222222 | E14: 1.1111111 | F14: 1.5277778 | G14: 0.97222222 | H14: 1.25 | I14: 0.13888889 | J14: 1.1111111 | K14: 0.83333333 | L14: 0.69444444
A15: J014 | B15: 0 | C15: 1 | D15: 4.3055556 | E15: 4.5833333 | F15: 5.6944444 | G15: 5.9722222 | H15: 4.5833333 | I15: 3.8888889 | J15: 5.9722222 | K15: 6.25 | L15: 2.7777778
A20: 4.3055556 | B20: 3.8888889 | D20: =AVERAGE(A20:A26) -> 4.8809524 | M20: 2.3611111 | N20: 2.5 | P20: =AVERAGE(M20:M26) -> 1.547619
A21: 3.1944444 | B21: 1.5277778 | D21: =STDEV(A20:A26) -> 3.7426442 | M21: 0.41666667 | N21: 1.1111111 | P21: =STDEV(M20:M26) -> 0.94685345
A22: 13.194444 | B22: 5 | D22: =AVERAGE(B20:B26) -> 5.3769841 | M22: 2.3611111 | N22: 3.6111111 | P22: =AVERAGE(N20:N23) -> 1.9791667
A23: 2.5 | B23: 10.416667 | D23: =STDEV(B20:B26) -> 3.1607668 | M23: 0.69444444 | N23: 0.69444444 | P23: =STDEV(N20:N23) -> 1.3339842
A24: 2.6388889 | B24: 7.5 | M24: 0.83333333
A25: 4.0277778 | B25: 7.0833333 | M25: 1.3888889
A26: 4.3055556 | B26: 2.2222222 | M26: 2.7777778

Sheet JOGGNGSpeed
A1: participants | B1: interGroup | C1: cwGroup | D1: sess1 | E1: sess2 | F1: sess3 | G1: sess4 | H1: sess5 | I1: sess6 | J1: sess7 | K1: sess8 | L1: sess9
A2: J001 | B2: 1 | C2: 1 | D2: 0.26113596 | E2: 0.26039072 | F2: 0.25973608 | G2: nan | H2: nan | I2: nan | J2: nan | K2: nan | L2: nan
A3: J002 | B3: 0 | C3: 1 | D3: 0.26346203 | E3: 0.2644068 | F3: 0.26487008 | G3: 0.26651736 | H3: 0.26877088 | I3: 0.27184017 | J3: 0.27566424 | K3: 0.2791548 | L3: 0.28237152
A4: J003 | B4: 1 | C4: 11 | D4: 0.1790867 | E4: 0.23360977 | F4: 0.25435204 | G4: 0.25606813 | H4: 0.25576537 | I4: 0.26076077 | J4: 0.25988954 | K4: 0.2608916 | L4: 0.25864174
A5: J004 | B5: 0 | C5: 11 | D5: 0.25578629 | E5: 0.25790681 | F5: 0.25931633 | G5: 0.25969389 | H5: 0.25894874 | I5: 0.25780733 | J5: 0.25670544 | K5: 0.25528375 | L5: 0.25381556
A6: J005 | B6: 1 | C6: 1 | D6: 0.28089127 | E6: 0.27906419 | F6: 0.27727858 | G6: 0.27555145 | H6: 0.27387328 | I6: 0.27215894 | J6: nan | K6: nan | L6: nan
A7: J006 | B7: 0 | C7: 1 | D7: 0.26454689 | E7: 0.26387743 | F7: 0.26317354 | G7: 0.26246756 | H7: 0.26193539 | I7: 0.2618583 | J7: 0.26172727 | K7: 0.26180184 | L7: 0.26171818
A8: J007 | B8: 0 | C8: 11 | D8: 0.2531963 | E8: 0.2529846 | F8: 0.26514356 | G8: 0.27766249 | H8: 0.29500929 | I8: 0.30336554 | J8: 0.31119362 | K8: 0.32030335 | L8: 0.32710938
A9: J008 | B9: 1 | C9: 11 | D9: 0.25595581 | E9: 0.25474389 | F9: 0.25352601 | G9: 0.2539409 | H9: 0.25478005 | I9: 0.25605578 | J9: 0.258223 | K9: 0.26069634 | L9: 0.26508129
A10: J009 | B10: 1 | C10: 1 | D10: 0.25590694 | E10: 0.25583239 | F10: 0.25653674 | G10: 0.25660162 | H10: 0.25793343 | I10: 0.25949651 | J10: 0.26067901 | K10: 0.26145753 | L10: 0.26231682
A11: J010 | B11: 0 | C11: 11 | D11: 0.2484634 | E11: 0.24839463 | F11: 0.24856535 | G11: 0.24890865 | H11: 0.2504095 | I11: 0.25216646 | J11: 0.25376482 | K11: 0.25549416 | L11: 0.25715894
A12: J011 | B12: 0 | C12: 1 | D12: 0.27107117 | E12: 0.26977969 | F12: 0.2688119 | G12: 0.26803552 | H12: 0.26724888 | I12: 0.26669514 | J12: 0.26623932 | K12: 0.26562738 | L12: 0.26533158
A13: J012 | B13: 1 | C13: 1 | D13: 0.25469623 | E13: 0.2558509 | F13: 0.25686284 | G13: 0.25722311 | H13: nan | I13: nan | J13: nan | K13: nan | L13: nan
A14: J013 | B14: 1 | C14: 11 | D14: 0.31659795 | E14: 0.30634668 | F14: 0.29706471 | G14: 0.28822543 | H14: 0.28107346 | I14: 0.27364512 | J14: 0.26688464 | K14: 0.26030523 | L14: 0.25403251
A15: J014 | B15: 0 | C15: 1 | D15: 0.26231407 | E15: 0.25995387 | F15: 0.25792793 | G15: 0.25654152 | H15: 0.25509633 | I15: 0.25322914 | J15: 0.25168259 | K15: 0.25009544 | L15: 0.24845323

Sheet Sheet2
A1: group analysis | C1: pos is slower on it
A2: group | B2: assessment | C2: steps | D2: VMCPM | E2: AATapa | F2: AATaps | G2: AATava | H2: AATavs | I2: 6MWT | J2: Grip (KG*N) | K2: WHOQOL | L2: AIAS | M2: PES
A3: 0 | B3: 1 | C3: =AVERAGEIFS(Main!M2:M43,Main!B2:B43,"=0",Main!D2:D43,"=1") -> 7727.8197 | D3: =AVERAGEIFS(Main!O2:O43,Main!B2:B43,"=0",Main!D2:D43,"=1") -> 622.05714 | E3: =AVERAGEIFS(Main!Q2:Q43,Main!B2:B43,"=0",Main!D2:D43,"=1") -> 187.85922 | F3: =AVERAGEIFS(Main!R2:R43,Main!B2:B43,"=0",Main!D2:D43,"=1") -> 220.08977 | G3: =AVERAGEIFS(Main!S2:S43,Main!B2:B43,"=0",Main!D2:D43,"=1") -> 210.27379 | H3: =AVERAGEIFS(Main!T2:T43,Main!B2:B43,"=0",Main!D2:D43,"=1") -> 363.49237 | I3: =AVERAGEIFS(Main!Y2:Y43,Main!B2:B43,"=0",Main!D2:D43,"=1") -> 418.92857 | J3: =AVERAGEIFS(Main!Z2:Z43,Main!B2:B43,"=0",Main!D2:D43,"=1") -> 28.428571 | K3: =AVERAGEIFS(Main!U2:U43,Main!B2:B43,"=0",Main!D2:D43,"=1") -> 103.57143 | L3: =AVERAGEIFS(Main!V2:V43,Main!B2:B43,"=0",Main!D2:D43,"=1") -> 10.571429 | M3: =AVERAGEIFS(Main!X2:X43,Main!B2:B43,"=0",Main!D2:D43,"=1") -> 1.6428571
B4: 2 | C4: =AVERAGEIFS(Main!M2:M43,Main!B2:B43,"=0",Main!D2:D43,"=2") -> 8932.6862 | D4: =AVERAGEIFS(Main!O2:O43,Main!B2:B43,"=0",Main!D2:D43,"=2") -> 664.04286 | E4: =AVERAGEIFS(Main!Q2:Q43,Main!B2:B43,"=0",Main!D2:D43,"=2") -> 187.40038 | F4: =AVERAGEIFS(Main!R2:R43,Main!B2:B43,"=0",Main!D2:D43,"=2") -> 239.79177 | G4: =AVERAGEIFS(Main!S2:S43,Main!B2:B43,"=0",Main!D2:D43,"=2") -> 37.794888 | H4: =AVERAGEIFS(Main!T2:T43,Main!B2:B43,"=0",Main!D2:D43,"=2") -> 74.974471 | I4: =AVERAGEIFS(Main!Y2:Y43,Main!B2:B43,"=0",Main!D2:D43,"=2") -> 439.28571 | J4: =AVERAGEIFS(Main!Z2:Z43,Main!B2:B43,"=0",Main!D2:D43,"=2") -> 29.142857 | K4: =AVERAGEIFS(Main!U2:U43,Main!B2:B43,"=0",Main!D2:D43,"=2") -> 104.14286 | L4: =AVERAGEIFS(Main!V2:V43,Main!B2:B43,"=0",Main!D2:D43,"=2") -> 10.857143 | M4: =AVERAGEIFS(Main!X2:X43,Main!B2:B43,"=0",Main!D2:D43,"=2") -> 1.7142857
B5: 3 | C5: =AVERAGEIFS(Main!M2:M43,Main!B2:B43,"=0",Main!D2:D43,"=3") -> 6209.0918 | D5: =AVERAGEIFS(Main!O2:O43,Main!B2:B43,"=0",Main!D2:D43,"=3") -> 546.5 | E5: =AVERAGEIFS(Main!Q2:Q43,Main!B2:B43,"=0",Main!D2:D43,"=3") -> 126.72639 | F5: =AVERAGEIFS(Main!R2:R43,Main!B2:B43,"=0",Main!D2:D43,"=3") -> 88.326401 | G5: =AVERAGEIFS(Main!S2:S43,Main!B2:B43,"=0",Main!D2:D43,"=3") -> 114.6218 | H5: =AVERAGEIFS(Main!T2:T43,Main!B2:B43,"=0",Main!D2:D43,"=3") -> 104.59524 | I5: =AVERAGEIFS(Main!Y2:Y43,Main!B2:B43,"=0",Main!D2:D43,"=3") -> 458.57143 | J5: =AVERAGEIFS(Main!Z2:Z43,Main!B2:B43,"=0",Main!D2:D43,"=3") -> 31.285714 | K5: =AVERAGEIFS(Main!U2:U43,Main!B2:B43,"=0",Main!D2:D43,"=3") -> 106 | L5: =AVERAGEIFS(Main!V2:V43,Main!B2:B43,"=0",Main!D2:D43,"=3") -> 11.571429 | M5: =AVERAGEIFS(Main!X2:X43,Main!B2:B43,"=0",Main!D2:D43,"=3") -> 1.6785714
A7: 1 | B7: 1 | C7: =AVERAGEIFS(Main!M2:M43,Main!B2:B43,"=1",Main!D2:D43,"=1") -> 4993.6131 | D7: =AVERAGEIFS(Main!O2:O43,Main!B2:B43,"=1",Main!D2:D43,"=1") -> 447.41429 | E7: =AVERAGEIFS(Main!Q5:Q46,Main!B5:B46,"=1",Main!D5:D46,"=1") -> 44.40227 | F7: =AVERAGEIFS(Main!R5:R46,Main!B5:B46,"=1",Main!D5:D46,"=1") -> 433.54498 | G7: =AVERAGEIFS(Main!S5:S46,Main!B5:B46,"=1",Main!D5:D46,"=1") -> 195.25255 | H7: =AVERAGEIFS(Main!T5:T46,Main!B5:B46,"=1",Main!D5:D46,"=1") -> 145.42979 | I7: =AVERAGEIFS(Main!Y5:Y46,Main!B5:B46,"=1",Main!D5:D46,"=1") -> 415 | J7: =AVERAGEIFS(Main!Z5:Z46,Main!B5:B46,"=1",Main!D5:D46,"=1") -> 26.5 | K7: =AVERAGEIFS(Main!U5:U46,Main!B5:B46,"=1",Main!D5:D46,"=1") -> 102.33333 | L7: =AVERAGEIFS(Main!V5:V46,Main!B5:B46,"=1",Main!D5:D46,"=1") -> 11.166667 | M7: =AVERAGEIFS(Main!X5:X46,Main!B5:B46,"=1",Main!D5:D46,"=1") -> 1.8333333
B8: 2 | C8: =AVERAGEIFS(Main!M2:M43,Main!B2:B43,"=1",Main!D2:D43,"=2") -> 5108.4209 | D8: =AVERAGEIFS(Main!O2:O43,Main!B2:B43,"=1",Main!D2:D43,"=2") -> 455.9 | E8: =AVERAGEIFS(Main!Q5:Q46,Main!B5:B46,"=1",Main!D5:D46,"=2") -> 19.986369 | F8: =AVERAGEIFS(Main!R5:R46,Main!B5:B46,"=1",Main!D5:D46,"=2") -> 165.37846 | G8: =AVERAGEIFS(Main!S5:S46,Main!B5:B46,"=1",Main!D5:D46,"=2") -> 43.737168 | H8: =AVERAGEIFS(Main!T5:T46,Main!B5:B46,"=1",Main!D5:D46,"=2") -> 12.541818 | I8: =AVERAGEIFS(Main!Y5:Y46,Main!B5:B46,"=1",Main!D5:D46,"=2") -> 450 | J8: =AVERAGEIFS(Main!Z5:Z46,Main!B5:B46,"=1",Main!D5:D46,"=2") -> 27.5 | K8: =AVERAGEIFS(Main!U5:U46,Main!B5:B46,"=1",Main!D5:D46,"=2") -> 104 | L8: =AVERAGEIFS(Main!V5:V46,Main!B5:B46,"=1",Main!D5:D46,"=2") -> 10 | M8: =AVERAGEIFS(Main!X5:X46,Main!B5:B46,"=1",Main!D5:D46,"=2") -> 1.9583333
B9: 3 | C9: =AVERAGEIFS(Main!M2:M43,Main!B2:B43,"=1",Main!D2:D43,"=3") -> 4854.7715 | D9: =AVERAGEIFS(Main!O2:O43,Main!B2:B43,"=1",Main!D2:D43,"=3") -> 490.4 | E9: =AVERAGEIFS(Main!Q5:Q46,Main!B5:B46,"=1",Main!D5:D46,"=3") -> -138.8573 | F9: =AVERAGEIFS(Main!R5:R46,Main!B5:B46,"=1",Main!D5:D46,"=3") -> 44.060145 | G9: =AVERAGEIFS(Main!S5:S46,Main!B5:B46,"=1",Main!D5:D46,"=3") -> 35.208073 | H9: =AVERAGEIFS(Main!T5:T46,Main!B5:B46,"=1",Main!D5:D46,"=3") -> 0.82099528 | I9: =AVERAGEIFS(Main!Y5:Y46,Main!B5:B46,"=1",Main!D5:D46,"=3") -> 433.75 | J9: =AVERAGEIFS(Main!Z5:Z46,Main!B5:B46,"=1",Main!D5:D46,"=3") -> 28.666667 | K9: =AVERAGEIFS(Main!U5:U46,Main!B5:B46,"=1",Main!D5:D46,"=3") -> 102.66667 | L9: =AVERAGEIFS(Main!V5:V46,Main!B5:B46,"=1",Main!D5:D46,"=3") -> 9.5 | M9: =AVERAGEIFS(Main!X5:X46,Main!B5:B46,"=0",Main!D5:D46,"=3") -> 1.6785714

Sheet Sheet1
B1: change
A2: group | B2: steps | C2: VMCPM | D2: AATapa | E2: AATaps | F2: AATava | G2: AATavs | H2: 6MWT | I2: Grip (KG*N) | J2: WHOQOL | K2: AIAS | L2: PES
A3: 0 | B3: =Sheet2!C4-Sheet2!C3 -> 1204.8665 | C3: =Sheet2!D4-Sheet2!D3 -> 41.985714 | D3: =Sheet2!E4-Sheet2!E3 -> -0.45884421 | E3: =Sheet2!F4-Sheet2!F3 -> 19.701998 | F3: =Sheet2!G4-Sheet2!G3 -> -172.4789 | G3: =Sheet2!H4-Sheet2!H3 -> -288.5179 | H3: =Sheet2!I4-Sheet2!I3 -> 20.357143 | I3: =Sheet2!J4-Sheet2!J3 -> 0.71428571 | ... L3: =Sheet2!M4-Sheet2!M3 -> 0.071428571
A4: 1 | B4: =Sheet2!C8-Sheet2!C7 -> 114.80782 | C4: =Sheet2!D8-Sheet2!D7 -> 8.4857143 | D4: =Sheet2!E8-Sheet2!E7 -> -24.415901 | E4: =Sheet2!F8-Sheet2!F7 -> -268.16652 | F4: =Sheet2!G8-Sheet2!G7 -> -151.51538 | G4: =Sheet2!H8-Sheet2!H7 -> -132.88797 | H4: =Sheet2!I8-Sheet2!I7 -> 35 | I4: =Sheet2!J8-Sheet2!J7 -> 1 | ... L4: =Sheet2!M8-Sheet2!M7 -> 0.125
B6: more steps in group 0 | C6: more counts in group 0 | D6: faster to approach activity in grou 1 | E6: faster to approach sedentary in group 0 | F6: faster to avoid active in group 0 | G6: faster to avoid sedentary group 0 | H6: greater walking in group 1 | I6: greater grip strength in group 1 | J6: greater QOL in group 1 | K6: greater want to be active in group 0 | L6: greater perception of wanting physical activity in group 1
