Workbook

Sheet Main
A1: ID | B1: InterGroup | C1: InterGroup2 | D1: Assessment | E1: Date | F1: Age | G1: Sex | H1: Who recruited? | I1: Height (cm) | J1: Height (ft) | K1: Height (inch) | L1: Weight (kg) | M1: Weight (lbs) | N1: Steps | O1: inactivePrc | P1: lightPrc | Q1: modPrc | R1: vigPrc | S1: AATapa | T1: AATaps | U1: AATava | V1: AATavs | W1: PES | X1: WHOQOL | Y1: Affect | Z1: Instrum | AA1: 6MWT | AB1: Grip (KG*N) | AG1: inactiveMins | AH1: lightMins | AI1: modMins | AJ1: vigMins | AK1: totalMins
A2: J001 | B2: 1 | C2: 1 | D2: 1 | E2: 250403 | F2: 75 | G2: F | H2: COA | I2: 165 | J2: =INT(ROUND(I2 / 2.54 *8, 0) / 96) -> 5 | K2: =ROUND((I2 / 2.54 - J2 * 12) * 8,0) / 8 -> 5 | L2: 65 | M2: =L2*2.2 -> 143 | N2: 3665.5 | O2: =AG2*100/AK2 -> 74.418525 | P2: =AH2*100/AK2 -> 21.306294 | Q2: =AI2*100/AK2 -> 4.2346149 | R2: =AJ2*100/AK2 -> 0.040566108 | S2: -622.56548 | T2: -301.35714 | U2: -298.24547 | V2: -119.49547 | W2: 2.5 | X2: 119 | Y2: 14 | Z2: 14 | AA2: 435 | AB2: 27 | AD2: =O2/(AK2/60)*16*7 -> 811.47224 | AE2: =P2/(AK2/60)*16*7 -> 232.32744 | AF2: =Q2/(AK2/60)*16*7 -> 46.17496 | AG2: 458.625 | AH2: 131.306 | AI2: 26.097 | AJ2: 0.25 | AK2: 616.278
A3: J001 | B3: 1 | C3: 1 | D3: 2 | E3: 250505 | N3: 3926 | O3: =AG3*100/AK3 -> 77.837262 | P3: =AH3*100/AK3 -> 17.483745 | Q3: =AI3*100/AK3 -> 4.630252 | R3: =AJ3*100/AK3 -> 0.048741172 | S3: -170.14015 | T3: -4.7651515 | U3: -28.009058 | V3: 1.8478261 | W3: 2.75 | X3: 120 | Y3: 12 | Z3: 12 | AA3: 495 | AB3: 20 | AD3: =O3/(AK3/60)*16*7 -> 833.16566 | AE3: =P3/(AK3/60)*16*7 -> 187.14502 | AF3: =Q3/(AK3/60)*16*7 -> 49.561956 | AG3: 488.667 | AH3: 109.764 | AI3: 29.069 | AJ3: 0.306 | AK3: 627.806
A4: J001 | B4: 1 | C4: 1 | D4: 3 | E4: 250603 | N4: 3620 | O4: =AG4*100/AK4 -> 71.456393 | P4: =AH4*100/AK4 -> 23.560086 | Q4: =AI4*100/AK4 -> 4.9337759 | R4: =AJ4*100/AK4 -> 0.049937003 | S4: -44.576087 | T4: 75.833333 | U4: -98.458333 | V4: 168.07971 | W4: 1.5 | X4: 109 | Y4: 12 | Z4: 12 | AA4: 457.5 | AB4: 24 | AD4: =O4/(AK4/60)*16*7 -> 922.27299 | AE4: =P4/(AK4/60)*16*7 -> 304.08519 | AF4: =Q4/(AK4/60)*16*7 -> 63.679231 | AG4: 372.042 | AH4: 122.667 | AI4: 25.688 | AJ4: 0.26 | AK4: 520.656
A5: J002 | B5: 0 | C5: 1 | D5: 1 | E5: 250414 | F5: 70 | G5: F | H5: COA | I5: 171 | J5: =INT(ROUND(I5 / 2.54 *8, 0) / 96) -> 5 | K5: =ROUND((I5 / 2.54 - J5 * 12) * 8,0) / 8 -> 7.375 | L5: 55.2 | M5: =L5*2.2 -> 121.44 | N5: 8572.1429 | O5: =AG5*100/AK5 -> 83.614041 | P5: =AH5*100/AK5 -> 8.577088 | Q5: =AI5*100/AK5 -> 7.7979886 | R5: =AJ5*100/AK5 -> 0.010752451 | S5: 49.072464 | T5: 54.036232 | U5: 88.944746 | V5: 833.55542 | W5: 2 | X5: 129 | Y5: 14 | Z5: 14 | AA5: 532.5 | AB5: 30 | AD5: =O5/(AK5/60)*16*7 -> 727.91033 | AE5: =P5/(AK5/60)*16*7 -> 74.66869 | AF5: =Q5/(AK5/60)*16*7 -> 67.886164 | AG5: 645.431 | AH5: 66.208 | AI5: 60.194 | AJ5: 0.083 | AK5: 771.917
A6: J002 | B6: 0 | C6: 1 | D6: 2 | E6: 250602 | N6: 8715 | O6: =AG6*100/AK6 -> 60.623493 | P6: =AH6*100/AK6 -> 31.43 | Q6: =AI6*100/AK6 -> 7.9465067 | R6: =AJ6*100/AK6 -> 0 | S6: 151.84524 | T6: 659.17857 | U6: 48.446558 | V6: 171.97373 | W6: 4 | X6: 127 | Y6: 14 | Z6: 14 | AA6: 540 | AB6: 29 | AD6: =O6/(AK6/60)*16*7 -> 472.60239 | AE6: =P6/(AK6/60)*16*7 -> 245.01876 | AF6: =Q6/(AK6/60)*16*7 -> 61.948559 | AG6: 522.583 | AH6: 270.931 | AI6: 68.5 | AJ6: 0 | AK6: 862.014
A7: J002 | B7: 0 | C7: 1 | D7: 3 | E7: 250707 | N7: 5360.5714 | O7: =AG7*100/AK7 -> 78.500114 | P7: =AH7*100/AK7 -> 17.306973 | Q7: =AI7*100/AK7 -> 4.1587258 | R7: =AJ7*100/AK7 -> 0.03406346 | S7: 60.306159 | T7: 112.1558 | U7: -54.602026 | V7: 226.7654 | W7: 4 | X7: 130 | Y7: 14 | Z7: 14 | AA7: 525 | AB7: 35 | AD7: =O7/(AK7/60)*16*7 -> 655.80958 | AE7: =P7/(AK7/60)*16*7 -> 144.58678 | AF7: =Q7/(AK7/60)*16*7 -> 34.743035 | AG7: 631.44 | AH7: 139.214 | AI7: 33.452 | AJ7: 0.274 | AK7: 804.381
A8: J003 | B8: 1 | C8: 11 | D8: 1 | E8: 250414 | F8: 68 | G8: M | H8: COA | I8: 169 | J8: =INT(ROUND(I8 / 2.54 *8, 0) / 96) -> 5 | K8: =ROUND((I8 / 2.54 - J8 * 12) * 8,0) / 8 -> 6.5 | L8: 54.8 | M8: =L8*2.2 -> 120.56 | N8: 10237.857 | O8: =AG8*100/AK8 -> 73.915571 | P8: =AH8*100/AK8 -> 15.98874 | Q8: =AI8*100/AK8 -> 9.9925228 | R8: =AJ8*100/AK8 -> 0.10330146 | S8: -87.643939 | T8: 504.96439 | U8: 365.14427 | V8: -32.431818 | W8: 2.75 | X8: 118 | Y8: 14 | Z8: 14 | AA8: 510 | AB8: 48 | AD8: =O8/(AK8/60)*16*7 -> 671.61176 | AE8: =P8/(AK8/60)*16*7 -> 145.27691 | AF8: =Q8/(AK8/60)*16*7 -> 90.794074 | AG8: 546.667 | AH8: 118.25 | AI8: 73.903 | AJ8: 0.764 | AK8: 739.583
A9: J003 | B9: 1 | C9: 11 | D9: 2 | E9: 250602 | N9: 8895.2857 | O9: =AG9*100/AK9 -> 45.85011 | P9: =AH9*100/AK9 -> 44.922924 | Q9: =AI9*100/AK9 -> 9.1946323 | R9: =AJ9*100/AK9 -> 0.032332875 | S9: -71.471218 | T9: 456.01985 | U9: 394.69565 | V9: 52.655797 | W9: 2.75 | X9: 122 | Y9: 13 | Z9: 14 | AA9: 570 | AB9: 44 | AD9: =O9/(AK9/60)*16*7 -> 358.35147 | AE9: =P9/(AK9/60)*16*7 -> 351.10485 | AF9: =Q9/(AK9/60)*16*7 -> 71.86264 | AG9: 394.222 | AH9: 386.25 | AI9: 79.056 | AJ9: 0.278 | AK9: 859.806
A10: J003 | B10: 1 | C10: 11 | D10: 3 | E10: 250707 | N10: 6312.5714 | O10: =AG10*100/AK10 -> 75.58099 | P10: =AH10*100/AK10 -> 19.350444 | Q10: =AI10*100/AK10 -> 4.9849891 | R10: =AJ10*100/AK10 -> 0.083576715 | S10: -5.1166008 | T10: 333.78261 | U10: 98.457016 | V10: -55.405303 | W10: 3 | X10: 125 | Y10: 12 | Z10: 14 | AA10: 555 | AB10: 48 | AD10: =O10/(AK10/60)*16*7 -> 668.4877 | AE10: =P10/(AK10/60)*16*7 -> 171.14798 | AF10: =Q10/(AK10/60)*16*7 -> 44.090503 | AG10: 574.25 | AH10: 147.021 | AI10: 37.875 | AJ10: 0.635 | AK10: 759.781
A11: J004 | B11: 0 | C11: 11 | D11: 1 | E11: 250416 | F11: 65 | G11: F | H11: COA/perley | I11: 159 | J11: =INT(ROUND(I11 / 2.54 *8, 0) / 96) -> 5 | K11: =ROUND((I11 / 2.54 - J11 * 12) * 8,0) / 8 -> 2.625 | L11: 51.7 | M11: =L11*2.2 -> 113.74 | N11: 8501.1667 | O11: =AG11*100/AK11 -> 30.179831 | P11: =AH11*100/AK11 -> 63.821885 | Q11: =AI11*100/AK11 -> 5.9563229 | R11: =AJ11*100/AK11 -> 0.041857431 | S11: 158.60054 | T11: -90.881341 | U11: -331.02083 | V11: 893.75272 | W11: 2 | X11: 107 | Y11: 10 | Z11: 12 | AA11: 412.5 | AB11: 36 | AD11: =O11/(AK11/60)*16*7 -> 210.64619 | AE11: =P11/(AK11/60)*16*7 -> 445.45765 | AF11: =Q11/(AK11/60)*16*7 -> 41.573351 | AG11: 290.569 | AH11: 614.472 | AI11: 57.347 | AJ11: 0.403 | AK11: 962.792
A12: J004 | B12: 0 | C12: 11 | D12: 2 | E12: 250514 | N12: 10406.714 | O12: =AG12*100/AK12 -> 74.812099 | P12: =AH12*100/AK12 -> 19.13831 | Q12: =AI12*100/AK12 -> 6.0395171 | R12: =AJ12*100/AK12 -> 0.010073997 | S12: 156.52536 | T12: -166.6413 | U12: -269.66667 | V12: -93.625 | W12: 2 | X12: 108 | Y12: 10 | Z12: 12 | AA12: 457.5 | AB12: 34 | AD12: =O12/(AK12/60)*16*7 -> 522.12105 | AE12: =P12/(AK12/60)*16*7 -> 133.56816 | AF12: =Q12/(AK12/60)*16*7 -> 42.150388 | AG12: 720.347 | AH12: 184.278 | AI12: 58.153 | AJ12: 0.097 | AK12: 962.875
A13: J004 | B13: 0 | C13: 11 | D13: 3 | E13: 250617 | N13: 7257.7143 | O13: =AG13*100/AK13 -> 76.281449 | P13: =AH13*100/AK13 -> 19.902552 | Q13: =AI13*100/AK13 -> 3.79188 | R13: =AJ13*100/AK13 -> 0.024119796 | S13: 194.34692 | T13: 24.160326 | U13: -11.9375 | V13: -20.770833 | W13: 2 | X13: 106 | Y13: 10 | Z13: 12 | AA13: 495 | AB13: 38 | AD13: =O13/(AK13/60)*16*7 -> 577.7608 | AE13: =P13/(AK13/60)*16*7 -> 150.74326 | AF13: =Q13/(AK13/60)*16*7 -> 28.719953 | AG13: 676.798 | AH13: 176.583 | AI13: 33.643 | AJ13: 0.214 | AK13: 887.238
A14: J005 | B14: 1 | C14: 1 | D14: 1 | E14: 250430 | F14: 70 | G14: M | H14: Perley | I14: 177 | J14: =INT(ROUND(I14 / 2.54 *8, 0) / 96) -> 5 | K14: =ROUND((I14 / 2.54 - J14 * 12) * 8,0) / 8 -> 9.625 | L14: 90.5 | M14: 199.6 | N14: 2794.6667 | O14: =AG14*100/AK14 -> 80.582658 | P14: =AH14*100/AK14 -> 17.518126 | Q14: =AI14*100/AK14 -> 1.8899286 | R14: =AJ14*100/AK14 -> 0.0092881403 | S14: 124.39583 | T14: -10.229167 | U14: -127.17391 | V14: 326.49275 | W14: 2.25 | X14: 112 | Y14: 12 | Z14: 14 | AA14: 322.5 | AB14: 26 | AD14: =O14/(AK14/60)*16*7 -> 750.69725 | AE14: =P14/(AK14/60)*16*7 -> 163.19651 | AF14: =Q14/(AK14/60)*16*7 -> 17.606322 | AG14: 581.283 | AH14: 126.367 | AI14: 13.633 | AJ14: 0.067 | AK14: 721.35
A15: J005 | B15: 1 | C15: 1 | D15: 2 | E15: 250523 | N15: 3704.2857 | O15: =AG15*100/AK15 -> 80.660232 | P15: =AH15*100/AK15 -> 17.745497 | Q15: =AI15*100/AK15 -> 1.583943 | R15: =AJ15*100/AK15 -> 0.010204709 | S15: 99.729167 | T15: -61.395833 | U15: 78.826087 | V15: 205.52174 | W15: 2 | X15: 115 | Y15: 12 | Z15: 13 | AA15: 435 | AB15: 29 | AD15: =O15/(AK15/60)*16*7 -> 666.42498 | AE15: =P15/(AK15/60)*16*7 -> 146.61553 | AF15: =Q15/(AK15/60)*16*7 -> 13.086736 | AG15: 656.05 | AH15: 144.333 | AI15: 12.883 | AJ15: 0.083 | AK15: 813.35
A16: J005 | B16: 1 | C16: 1 | D16: 3 | E16: 250715 | N16: 6651.125 | O16: =AG16*100/AK16 -> 68.555519 | P16: =AH16*100/AK16 -> 27.933151 | Q16: =AI16*100/AK16 -> 3.4992775 | R16: =AJ16*100/AK16 -> 0.012187005 | S16: 105.16667 | T16: 265.29167 | U16: 33.169384 | V16: 124.39764 | W16: 1.25 | X16: 108 | Y16: 10 | Z16: 14 | AA16: 405 | AB16: 27 | AD16: =O16/(AK16/60)*16*7 -> 616.9746 | AE16: =P16/(AK16/60)*16*7 -> 251.38815 | AF16: =Q16/(AK16/60)*16*7 -> 31.492218 | AG16: 511.902 | AH16: 208.576 | AI16: 26.129 | AJ16: 0.091 | AK16: 746.697
A17: J006 | B17: 0 | C17: 1 | D17: 1 | E17: 250515 | F17: 79 | G17: M | H17: Perley | I17: 177 | J17: =INT(ROUND(I17 / 2.54 *8, 0) / 96) -> 5 | K17: =ROUND((I17 / 2.54 - J17 * 12) * 8,0) / 8 -> 9.625 | L17: =M17/2.2 -> 99.090909 | M17: 218 | N17: 2131.3333 | O17: =AG17*100/AK17 -> 86.784652 | P17: =AH17*100/AK17 -> 12.631132 | Q17: =AI17*100/AK17 -> 0.58421589 | R17: =AJ17*100/AK17 -> 0 | S17: 161.79464 | T17: 607.90153 | U17: 661.03837 | V17: 207.61575 | W17: 0.75 | X17: 100 | Y17: 8 | Z17: 12 | AA17: 337.5 | AB17: 32 | AD17: =O17/(AK17/60)*16*7 -> 1536.8089 | AE17: =P17/(AK17/60)*16*7 -> 223.67592 | AF17: =Q17/(AK17/60)*16*7 -> 10.345472 | AG17: 329.333 | AH17: 47.933 | AI17: 2.217 | AJ17: 0 | AK17: 379.483
A18: J006 | B18: 0 | C18: 1 | D18: 2 | E18: 250714 | N18: 1378.75 | O18: =AG18*100/AK18 -> 92.347544 | P18: =AH18*100/AK18 -> 7.4005372 | Q18: =AI18*100/AK18 -> 0.25191885 | R18: =AJ18*100/AK18 -> 0 | S18: 26.070393 | T18: 139.22981 | U18: 45.734091 | V18: 28.552273 | W18: 0 | X18: 103 | Y18: 11 | Z18: 12 | AA18: 337.5 | AB18: 32 | AD18: =O18/(AK18/60)*16*7 -> 949.78534 | AE18: =P18/(AK18/60)*16*7 -> 76.113792 | AF18: =Q18/(AK18/60)*16*7 -> 2.5909605 | AG18: 603.385 | AH18: 48.354 | AI18: 1.646 | AJ18: 0 | AK18: 653.385
A19: J006 | B19: 0 | C19: 1 | D19: 3 | E19: 250808 | N19: 1604.5714 | O19: =AG19*100/AK19 -> 88.06841 | P19: =AH19*100/AK19 -> 11.538264 | Q19: =AI19*100/AK19 -> 0.39092397 | R19: =AJ19*100/AK19 -> 0.0024025178 | S19: 132.47875 | T19: -224.69697 | U19: 130.01812 | V19: 58.192029 | W19: 0.25 | X19: 100 | Y19: 10 | Z19: 13 | AA19: 367.5 | AB19: 32 | AD19: =O19/(AK19/60)*16*7 -> 1015.6124 | AE19: =P19/(AK19/60)*16*7 -> 133.06024 | AF19: =Q19/(AK19/60)*16*7 -> 4.5081687 | AG19: 513.194 | AH19: 67.236 | AI19: 2.278 | AJ19: 0.014 | AK19: 582.722
A20: J007 | B20: 0 | C20: 11 | D20: 1 | E20: 250611 | F20: 72 | G20: F | H20: COA | I20: 162 | J20: =INT(ROUND(I20 / 2.54 *8, 0) / 96) -> 5 | K20: =ROUND((I20 / 2.54 - J20 * 12) * 8,0) / 8 -> 3.75 | L20: 66.3 | M20: 146.2 | N20: 7039.7143 | O20: =AG20*100/AK20 -> 82.040201 | P20: =AH20*100/AK20 -> 12.057256 | Q20: =AI20*100/AK20 -> 5.9025434 | R20: =AJ20*100/AK20 -> 0 | S20: 459.47101 | T20: 367.63768 | U20: 581.59058 | V20: 165.41667 | W20: 0 | X20: 109 | Y20: 10 | Z20: 14 | AA20: 435 | AB20: 23 | AD20: =O20/(AK20/60)*16*7 -> 734.02027 | AE20: =P20/(AK20/60)*16*7 -> 107.87724 | AF20: =Q20/(AK20/60)*16*7 -> 52.81053 | AG20: 616.19 | AH20: 90.56 | AI20: 44.333 | AJ20: 0 | AK20: 751.083
A21: J007 | B21: 0 | C21: 11 | D21: 2 | E21: 250721 | N21: 8007.8571 | O21: =AG21*100/AK21 -> 83.372377 | P21: =AH21*100/AK21 -> 10.883674 | Q21: =AI21*100/AK21 -> 5.7405724 | R21: =AJ21*100/AK21 -> 0.0035020268 | S21: 272.90314 | T21: 235.375 | U21: 62.742754 | V21: 161.97645 | W21: 0.75 | X21: 114 | Y21: 9 | Z21: 12 | AA21: 412.5 | AB21: 24 | AD21: =O21/(AK21/60)*16*7 -> 700.73351 | AE21: =P21/(AK21/60)*16*7 -> 91.475803 | AF21: =Q21/(AK21/60)*16*7 -> 48.248732 | AG21: 666.593 | AH21: 87.019 | AI21: 45.898 | AJ21: 0.028 | AK21: 799.537
A22: J007 | B22: 0 | C22: 11 | D22: 3 | E22: 250808 | N22: 5277.4286 | O22: =AG22*100/AK22 -> 86.200374 | P22: =AH22*100/AK22 -> 8.8218574 | Q22: =AI22*100/AK22 -> 4.9777689 | R22: =AJ22*100/AK22 -> 0 | S22: 24.125 | T22: 243.94102 | U22: 357.08144 | V22: 107.60417 | W22: 0.5 | X22: 114 | Y22: 10 | Z22: 11 | AA22: 427.5 | AB22: 22 | AD22: =O22/(AK22/60)*16*7 -> 829.48473 | AE22: =P22/(AK22/60)*16*7 -> 84.890536 | AF22: =Q22/(AK22/60)*16*7 -> 47.89983 | AG22: 601.976 | AH22: 61.607 | AI22: 34.762 | AJ22: 0 | AK22: 698.345
A23: J008 | B23: 1 | C23: 11 | D23: 1 | E23: 250623 | F23: 61 | G23: F | H23: COA | I23: 143 | J23: =INT(ROUND(I23 / 2.54 *8, 0) / 96) -> 4 | K23: =ROUND((I23 / 2.54 - J23 * 12) * 8,0) / 8 -> 8.25 | L23: =M23/2.2 -> 84.090909 | M23: 185 | N23: 3490.625 | O23: =AG23*100/AK23 -> 82.087422 | P23: =AH23*100/AK23 -> 15.940391 | Q23: =AI23*100/AK23 -> 1.9606497 | R23: =AJ23*100/AK23 -> 0.011399924 | S23: 199.82609 | T23: 88.826087 | U23: 308.53895 | V23: 389.2346 | W23: 1.5 | X23: 109 | Y23: 9 | Z23: 14 | AA23: 382.5 | AB23: 23 | AD23: =O23/(AK23/60)*16*7 -> 757.652 | AE23: =P23/(AK23/60)*16*7 -> 147.12691 | AF23: =Q23/(AK23/60)*16*7 -> 18.09644 | AG23: 597.658 | AH23: 116.058 | AI23: 14.275 | AJ23: 0.083 | AK23: 728.075
A24: J008 | B24: 1 | C24: 11 | D24: 2 | E24: 250729 | N24: 2594 | O24: =AG24*100/AK24 -> 82.334117 | P24: =AH24*100/AK24 -> 15.526609 | Q24: =AI24*100/AK24 -> 2.1373365 | R24: =AJ24*100/AK24 -> 0.0019374557 | S24: 90.371894 | T24: 158.52588 | U24: -77.341486 | V24: 81.491848 | W24: 3.25 | X24: 117 | Y24: 11 | Z24: 14 | AA24: 457.5 | AB24: 22 | AD24: =O24/(AK24/60)*16*7 -> 893.30475 | AE24: =P24/(AK24/60)*16*7 -> 168.45985 | AF24: =Q24/(AK24/60)*16*7 -> 23.189571 | AG24: 509.952 | AH24: 96.167 | AI24: 13.238 | AJ24: 0.012 | AK24: 619.369
A25: J008 | B25: 1 | C25: 11 | D25: 3 | E25: 250819 | N25: 2787.8571 | O25: =AG25*100/AK25 -> 79.228342 | P25: =AH25*100/AK25 -> 18.948251 | Q25: =AI25*100/AK25 -> 1.823407 | R25: =AJ25*100/AK25 -> 0 | S25: -644.44928 | T25: -438.44384 | U25: -156.19952 | V25: -127.50387 | W25: 3.25 | X25: 105 | Y25: 9 | Z25: 12 | AA25: 420 | AB25: 20 | AD25: =O25/(AK25/60)*16*7 -> 786.27055 | AE25: =P25/(AK25/60)*16*7 -> 188.04448 | AF25: =Q25/(AK25/60)*16*7 -> 18.095687 | AG25: 536.486 | AH25: 128.306 | AI25: 12.347 | AJ25: 0 | AK25: 677.139
A26: J009 | B26: 1 | C26: 1 | D26: 1 | E26: 250703 | F26: 62 | G26: F | H26: Perley | I26: 162 | J26: =INT(ROUND(I26 / 2.54 *8, 0) / 96) -> 5 | K26: =ROUND((I26 / 2.54 - J26 * 12) * 8,0) / 8 -> 3.75 | L26: =M26/2.2 -> 81.363636 | M26: 179 | N26: 9009.75 | O26: =AG26*100/AK26 -> 82.642062 | P26: =AH26*100/AK26 -> 9.5073756 | Q26: =AI26*100/AK26 -> 7.8335111 | R26: =AJ26*100/AK26 -> 0.017051019 | S26: -229.14583 | T26: 69.5625 | U26: 23.184783 | V26: -63.981884 | W26: 3.25 | X26: 104 | Y26: 12 | Z26: 13 | AA26: 442.5 | AB26: 22 | AD26: =O26/(AK26/60)*16*7 -> 757.54904 | AE26: =P26/(AK26/60)*16*7 -> 87.150575 | AF26: =Q26/(AK26/60)*16*7 -> 71.806882 | AG26: 605.844 | AH26: 69.698 | AI26: 57.427 | AJ26: 0.125 | AK26: 733.094
A27: J009 | B27: 1 | C27: 1 | D27: 2 | E27: 250807 | N27: 11848 | O27: =AG27*100/AK27 -> 74.812865 | P27: =AH27*100/AK27 -> 15.039242 | Q27: =AI27*100/AK27 -> 10.116032 | R27: =AJ27*100/AK27 -> 0.031733983 | S27: 8.120471 | T27: 218.07699 | U27: 17.997283 | V27: -112.35054 | W27: 3.25 | X27: 105 | Y27: 12 | Z27: 11 | AA27: 532.5 | AB27: 28 | AD27: =O27/(AK27/60)*16*7 -> 638.16081 | AE27: =P27/(AK27/60)*16*7 -> 128.28616 | AF27: =Q27/(AK27/60)*16*7 -> 86.290711 | AG27: 589.375 | AH27: 118.479 | AI27: 79.694 | AJ27: 0.25 | AK27: 787.799
A28: J009 | B28: 1 | C28: 1 | D28: 3 | E28: 250905 | N28: 7946.2222 | O28: =AG28*100/AK28 -> 78.696169 | P28: =AH28*100/AK28 -> 14.936113 | Q28: =AI28*100/AK28 -> 6.3581811 | R28: =AJ28*100/AK28 -> 0.0095373361 | S28: 53.422101 | T28: 292.63043 | U28: 122.04167 | V28: 65.208333 | W28: 4 | X28: 108 | Y28: 12 | Z28: 12 | AA28: 457.5 | AB28: 29 | AD28: =O28/(AK28/60)*16*7 -> 681.58219 | AE28: =P28/(AK28/60)*16*7 -> 129.36066 | AF28: =Q28/(AK28/60)*16*7 -> 55.067776 | AG28: 610.602 | AH28: 115.889 | AI28: 49.333 | AJ28: 0.074 | AK28: 775.898
A29: J010 | B29: 0 | C29: 11 | D29: 1 | E29: 250702 | F29: 64 | G29: M | H29: the good companions | I29: 172 | J29: =INT(ROUND(I29 / 2.54 *8, 0) / 96) -> 5 | K29: =ROUND((I29 / 2.54 - J29 * 12) * 8,0) / 8 -> 7.75 | L29: =M29/2.2 -> 85.909091 | M29: 189 | N29: 16352.143 | O29: =AG29*100/AK29 -> 71.127604 | P29: =AH29*100/AK29 -> 12.858848 | Q29: =AI29*100/AK29 -> 16.009035 | R29: =AJ29*100/AK29 -> 0.0045126241 | S29: 73.97192 | T29: 532.79603 | U29: 347.75543 | V29: 117.1721 | W29: 2.75 | X29: 102 | Y29: 12 | Z29: 12 | AA29: 517.5 | AB29: 32 | AD29: =O29/(AK29/60)*16*7 -> 599.14799 | AE29: =P29/(AK29/60)*16*7 -> 108.31734 | AF29: =Q29/(AK29/60)*16*7 -> 134.85315 | AG29: 567.429 | AH29: 102.583 | AI29: 127.714 | AJ29: 0.036 | AK29: 797.762
A30: J010 | B30: 0 | C30: 11 | D30: 2 | E30: 250806 | N30: 24100.625 | O30: =AG30*100/AK30 -> 65.546382 | P30: =AH30*100/AK30 -> 11.462542 | Q30: =AI30*100/AK30 -> 22.987294 | R30: =AJ30*100/AK30 -> 0.003781447 | S30: 124.6721 | T30: 247.98758 | U30: 66.958333 | V30: -79.875 | W30: 3 | X30: 104 | Y30: 12 | Z30: 14 | AA30: 577.5 | AB30: 32 | AD30: =O30/(AK30/60)*16*7 -> 537.29689 | AE30: =P30/(AK30/60)*16*7 -> 93.960761 | AF30: =Q30/(AK30/60)*16*7 -> 188.43148 | AG30: 537.344 | AH30: 93.969 | AI30: 188.448 | AJ30: 0.031 | AK30: 819.792
A31: J010 | B31: 0 | C31: 11 | D31: 3 | E31: 250905 | N31: 19023.875 | O31: =AG31*100/AK31 -> 71.235315 | P31: =AH31*100/AK31 -> 10.490333 | Q31: =AI31*100/AK31 -> 18.269255 | R31: =AJ31*100/AK31 -> 0.0050966359 | S31: 177.92029 | T31: 162.77717 | U31: 146.5 | V31: 179.375 | W31: 3 | X31: 106 | Y31: 12 | Z31: 12 | AA31: 585 | AB31: 36 | AD31: =O31/(AK31/60)*16*7 -> 580.89674 | AE31: =P31/(AK31/60)*16*7 -> 85.54465 | AF31: =Q31/(AK31/60)*16*7 -> 148.97879 | AG31: 587.031 | AH31: 86.448 | AI31: 150.552 | AJ31: 0.042 | AK31: 824.073
A32: J011 | B32: 0 | C32: 1 | D32: 1 | E32: 250702 | F32: 69 | G32: F | H32: the good companions | I32: 162 | J32: =INT(ROUND(I32 / 2.54 *8, 0) / 96) -> 5 | K32: =ROUND((I32 / 2.54 - J32 * 12) * 8,0) / 8 -> 3.75 | L32: =M32/2.2 -> 83.181818 | M32: 183 | N32: 2918.6667 | O32: =AG32*100/AK32 -> 89.697436 | P32: =AH32*100/AK32 -> 9.1382104 | Q32: =AI32*100/AK32 -> 1.1626289 | R32: =AJ32*100/AK32 -> 0.0016098116 | S32: 108.97357 | T32: 144.83523 | U32: 165.64229 | V32: 268.05138 | W32: 2 | X32: 76 | Y32: 10 | Z32: 14 | AA32: 322.5 | AB32: 30 | AD32: =O32/(AK32/60)*16*7 -> 693.10066 | AE32: =P32/(AK32/60)*16*7 -> 70.611825 | AF32: =Q32/(AK32/60)*16*7 -> 8.9837447 | AG32: 780.069 | AH32: 79.472 | AI32: 10.111 | AJ32: 0.014 | AK32: 869.667
A33: J011 | B33: 0 | C33: 1 | D33: 2 | E33: 250807 | N33: 1506.1429 | O33: =AG33*100/AK33 -> 91.944533 | P33: =AH33*100/AK33 -> 7.4457584 | Q33: =AI33*100/AK33 -> 0.6050404 | R33: =AJ33*100/AK33 -> 0.004801908 | S33: 283.44623 | T33: 339.94623 | U33: 96.971014 | V33: 314.05435 | W33: 0.5 | X33: 75 | Y33: 10 | Z33: 14 | AA33: 360 | AB33: 33 | AD33: =O33/(AK33/60)*16*7 -> 824.15047 | AE33: =P33/(AK33/60)*16*7 -> 66.740514 | AF33: =Q33/(AK33/60)*16*7 -> 5.4233169 | AG33: 689.31 | AH33: 55.821 | AI33: 4.536 | AJ33: 0.036 | AK33: 749.702
A34: J011 | B34: 0 | C34: 1 | D34: 3 | E34: 250902 | N34: 2106.8571 | O34: =AG34*100/AK34 -> 93.11276 | P34: =AH34*100/AK34 -> 5.6049768 | Q34: =AI34*100/AK34 -> 1.2807841 | R34: =AJ34*100/AK34 -> 0.0016137557 | S34: 183.46467 | T34: 176.21467 | U34: 64.771739 | V34: 111.35507 | W34: 0 | X34: 81 | Y34: 14 | Z34: 14 | AA34: 405 | AB34: 36 | AD34: =O34/(AK34/60)*16*7 -> 841.46296 | AE34: =P34/(AK34/60)*16*7 -> 50.652353 | AF34: =Q34/(AK34/60)*16*7 -> 11.574486 | AG34: 692.393 | AH34: 41.679 | AI34: 9.524 | AJ34: 0.012 | AK34: 743.607
A35: J012 | B35: 1 | C35: 1 | D35: 1 | E35: 250714 | F35: 70 | G35: F | H35: COA | I35: 161 | J35: =INT(ROUND(I35 / 2.54 *8, 0) / 96) -> 5 | K35: =ROUND((I35 / 2.54 - J35 * 12) * 8,0) / 8 -> 3.375 | L35: =M35/2.2 -> 76.727273 | M35: 168.8 | N35: 2776.75 | O35: =AG35*100/AK35 -> 88.291227 | P35: =AH35*100/AK35 -> 10.589786 | Q35: =AI35*100/AK35 -> 1.1070042 | R35: =AJ35*100/AK35 -> 0.012076072 | S35: 77.156291 | T35: 593.91613 | U35: 456.03409 | V35: 174.81126 | W35: 0 | X35: 64 | Y35: 12 | Z35: 13 | AA35: 457.5 | AB35: 18 | AD35: =O35/(AK35/60)*16*7 -> 551.14917 | AE35: =P35/(AK35/60)*16*7 -> 66.105683 | AF35: =Q35/(AK35/60)*16*7 -> 6.9103633 | AG35: 950.463 | AH35: 114 | AI35: 11.917 | AJ35: 0.13 | AK35: 1076.509
A36: J012 | B36: 1 | C36: 1 | D36: 2 | E36: 250731 | N36: 2862 | O36: =AG36*100/AK36 -> 89.293695 | P36: =AH36*100/AK36 -> 9.7018004 | Q36: =AI36*100/AK36 -> 1.0044161 | R36: =AJ36*100/AK36 -> 0 | S36: -23.179924 | T36: -10.50947 | U36: -38.21558 | V36: -87.086957 | W36: 0 | X36: 58 | Y36: 4 | Z36: 6 | AA36: 405 | AB36: 16 | AD36: =O36/(AK36/60)*16*7 -> 531.25034 | AE36: =P36/(AK36/60)*16*7 -> 57.72059 | AF36: =Q36/(AK36/60)*16*7 -> 5.9757452 | AG36: 1008.583 | AH36: 109.583 | AI36: 11.345 | AJ36: 0 | AK36: 1129.512
A37: J012 | B37: 1 | C37: 1 | D37: 3 | E37: 250902 | N37: 3028 | O37: =AG37*100/AK37 -> 88.762467 | P37: =AH37*100/AK37 -> 10.040283 | Q37: =AI37*100/AK37 -> 1.196406 | R37: =AJ37*100/AK37 -> 0.00084392617 | S37: -234.91667 | T37: -410.25 | U37: 55.321558 | V37: -6.8125 | W37: 1 | X37: 60 | Y37: 6 | Z37: 8 | AA37: 412.5 | AB37: 22 | AD37: =O37/(AK37/60)*16*7 -> 559.3203 | AE37: =P37/(AK37/60)*16*7 -> 63.266992 | AF37: =Q37/(AK37/60)*16*7 -> 7.5389316 | AG37: 946.602 | AH37: 107.074 | AI37: 12.759 | AJ37: 0.009 | AK37: 1066.444
A38: J013 | B38: 1 | C38: 11 | D38: 1 | E38: 250716 | F38: 66 | G38: F | H38: COA | I38: 163.5 | J38: =INT(ROUND(I38 / 2.54 *8, 0) / 96) -> 5 | K38: =ROUND((I38 / 2.54 - J38 * 12) * 8,0) / 8 -> 4.375 | L38: =M38/2.2 -> 76.363636 | M38: 168 | N38: 2980.1429 | O38: =AG38*100/AK38 -> 89.515821 | P38: =AH38*100/AK38 -> 9.2884805 | Q38: =AI38*100/AK38 -> 1.1903246 | R38: =AJ38*100/AK38 -> 0.0052571015 | S38: 181.82518 | T38: 1354.2299 | U38: 145.78714 | V38: 78.453804 | W38: 1.25 | X38: 107 | Y38: 8 | Z38: 12 | AA38: 375 | AB38: 22 | AD38: =O38/(AK38/60)*16*7 -> 702.75334 | AE38: =P38/(AK38/60)*16*7 -> 72.92019 | AF38: =Q38/(AK38/60)*16*7 -> 9.3447681 | AG38: 766.242 | AH38: 79.508 | AI38: 10.189 | AJ38: 0.045 | AK38: 855.985
A39: J013 | B39: 1 | C39: 11 | D39: 2 | E39: 250818 | N39: 1929.375 | O39: =AG39*100/AK39 -> 84.54512 | P39: =AH39*100/AK39 -> 14.866597 | Q39: =AI39*100/AK39 -> 0.58339809 | R39: =AJ39*100/AK39 -> 0.0047717079 | S39: 16.347826 | T39: 231.55336 | U39: -113.53895 | V39: -64.980978 | W39: 0.5 | X39: 107 | Y39: 8 | Z39: 12 | AA39: 300 | AB39: 26 | AD39: =O39/(AK39/60)*16*7 -> 645.47938 | AE39: =P39/(AK39/60)*16*7 -> 113.50249 | AF39: =Q39/(AK39/60)*16*7 -> 4.4540884 | AG39: 744.156 | AH39: 130.854 | AI39: 5.135 | AJ39: 0.042 | AK39: 880.188
A40: J013 | B40: 1 | C40: 11 | D40: 3 | E40: 250917 | N40: 3637.625 | O40: =AG40*100/AK40 -> 76.926355 | P40: =AH40*100/AK40 -> 20.75424 | Q40: =AI40*100/AK40 -> 2.3148911 | R40: =AJ40*100/AK40 -> 0.0044089165 | S40: -107.25 | T40: 221.35 | U40: 58.458333 | V40: 5.0416667 | W40: 1.5 | X40: 110 | Y40: 8 | Z40: 14 | AA40: 352.5 | AB40: 26 | AD40: =O40/(AK40/60)*16*7 -> 542.659 | AE40: =P40/(AK40/60)*16*7 -> 146.40594 | AF40: =Q40/(AK40/60)*16*7 -> 16.329859 | AG40: 732.812 | AH40: 197.708 | AI40: 22.052 | AJ40: 0.042 | AK40: 952.615
...

Sheet JOGGNGRT
A1: participants | B1: interGroup | C1: cwGroup | D1: sess1 | E1: sess2 | F1: sess3 | G1: sess4 | H1: sess5 | I1: sess6 | J1: sess7 | K1: sess8 | L1: sess9
A2: J001 | B2: 1 | C2: 1 | D2: 520.94229 | E2: 470.38487 | F2: 434.69877 | G2: nan | H2: nan | I2: nan | J2: nan | K2: nan | L2: nan
A3: J002 | B3: 0 | C3: 1 | D3: 494.49967 | E3: 464.79147 | F3: 474.94536 | G3: 456.01592 | H3: 454.42028 | I3: 425.7599 | J3: 425.5708 | K3: 414.96834 | L3: 397.98407
A4: J003 | B4: 1 | C4: 11 | D4: 454.5306 | E4: 385.45865 | F4: 413.12946 | G4: 423.5135 | H4: 400.32265 | I4: 393.70412 | J4: 395.40142 | K4: 385.85997 | L4: 393.93752
A5: J004 | B5: 0 | C5: 11 | D5: 517.85111 | E5: 505.45965 | F5: 496.57008 | G5: 488.80985 | H5: 497.89129 | I5: 505.63354 | J5: 488.52635 | K5: 481.00716 | L5: 495.16502
A6: J005 | B6: 1 | C6: 1 | D6: 506.23798 | E6: 514.83269 | F6: 541.61211 | G6: 523.95485 | H6: 539.7862 | I6: 541.74378 | J6: nan | K6: nan | L6: nan
A7: J006 | B7: 0 | C7: 1 | D7: 551.06558 | E7: 517.97335 | F7: 520.20994 | G7: 517.60516 | H7: 512.40785 | I7: 494.40108 | J7: 488.71587 | K7: 481.23252 | L7: 486.04719
A8: J007 | B8: 0 | C8: 11 | D8: 518.1789 | E8: 437.40122 | F8: 413.1288 | G8: 419.20568 | H8: 389.54431 | I8: 394.55408 | J8: 397.44485 | K8: 378.08115 | L8: 377.0858
A9: J008 | B9: 1 | C9: 11 | D9: 499.80134 | E9: 479.62326 | F9: 473.04129 | G9: 459.35308 | H9: 454.99852 | I9: 447.49151 | J9: 451.63139 | K9: 443.76914 | L9: 434.73876
A10: J009 | B10: 1 | C10: 1 | D10: 471.49357 | E10: 425.0117 | F10: 406.46904 | G10: 423.215 | H10: 396.90389 | I10: 407.00259 | J10: 409.12899 | K10: 400.738 | L10: 409.68968
A11: J010 | B11: 0 | C11: 11 | D11: 483.15825 | E11: 471.58097 | F11: 470.25922 | G11: 465.79091 | H11: 431.07994 | I11: 425.72733 | J11: 443.69631 | K11: 434.49102 | L11: 439.89829
A12: J011 | B12: 0 | C12: 1 | D12: 513.24505 | E12: 480.59949 | F12: 468.81004 | G12: 460.48336 | H12: 454.31161 | I12: 456.4544 | J12: 471.9643 | K12: 462.85629 | L12: 439.40713
A13: J012 | B13: 1 | C13: 1 | D13: 487.25106 | E13: 462.63625 | F13: 452.34947 | G13: 446.21426 | H13: nan | I13: nan | J13: nan | K13: nan | L13: nan
A14: J013 | B14: 1 | C14: 11 | D14: 486.26196 | E14: 476.96705 | F14: 467.00749 | G14: 484.17825 | H14: 444.69389 | I14: 493.95292 | J14: 476.08783 | K14: 478.4283 | L14: 481.03899
A15: J014 | B15: 0 | C15: 1 | D15: 509.43834 | E15: 447.1709 | F15: 413.00025 | G15: 394.39956 | H15: 385.64921 | I15: 408.32264 | J15: 393.4966 | K15: 394.19336 | L15: 404.14715
A17: 494.49967 | B17: 520.94229 | D17: =AVERAGEIF(B2:B15,0,D2:D15) -> 512.49099 | L17: 397.98407 | M17: 393.93752 | O17: =AVERAGE(L17:L23) -> 434.24781
A18: 517.85111 | B18: 454.5306 | D18: =STDEV(A17:A23) -> 21.381715 | L18: 495.16502 | M18: 434.73876 | O18: =STDEV(L17:L23) -> 44.611719
A19: 551.06558 | B19: 506.23798 | D19: =AVERAGEIF(B2:B15,1,D2:D15) -> 489.50269 | L19: 486.04719 | M19: 409.68968 | O19: =AVERAGE(M17:M23) -> 429.85124
A20: 518.1789 | B20: 499.80134 | D20: =STDEV(B17:B23) -> 22.126639 | L20: 377.0858 | M20: 481.03899 | O20: =STDEV(M17:M20) -> 38.036637
A21: 483.15825 | B21: 471.49357 | L21: 439.89829
A22: 513.24505 | B22: 487.25106 | L22: 439.40713
A23: 509.43834 | B23: 486.26196 | L23: 404.14715

Sheet JOGGNGError
A1: participants | B1: interGroup | C1: cwGroup | D1: sess1 | E1: sess2 | F1: sess3 | G1: sess4 | H1: sess5 | I1: sess6 | J1: sess7 | K1: sess8 | L1: sess9
A2: J001 | B2: 1 | C2: 1 | D2: 3.8888889 | E2: 1.8055556 | F2: 1.9444444 | G2: nan | H2: nan | I2: nan | J2: nan | K2: nan | L2: nan
A3: J002 | B3: 0 | C3: 1 | D3: 4.3055556 | E3: 4.5833333 | F3: 1.6666667 | G3: 2.9166667 | H3: 2.2222222 | I3: 1.5277778 | J3: 2.3611111 | K3: 1.6666667 | L3: 2.3611111
A4: J003 | B4: 1 | C4: 11 | D4: 1.5277778 | E4: 5 | F4: 2.6388889 | G4: 2.3611111 | H4: 2.7777778 | I4: 3.0555556 | J4: 2.9166667 | K4: 2.3611111 | L4: 2.5
A5: J004 | B5: 0 | C5: 11 | D5: 3.1944444 | E5: 0.69444444 | F5: 0.83333333 | G5: 1.5277778 | H5: 0.83333333 | I5: 0.97222222 | J5: 0.83333333 | K5: 0.83333333 | L5: 0.41666667
A6: J005 | B6: 1 | C6: 1 | D6: 5 | E6: 1.8055556 | F6: 2.9166667 | G6: 1.25 | H6: 1.6666667 | I6: 0.69444444 | J6: nan | K6: nan | L6: nan
A7: J006 | B7: 0 | C7: 1 | D7: 13.194444 | E7: 3.1944444 | F7: 3.1944444 | G7: 2.2222222 | H7: 2.0833333 | I7: 2.0833333 | J7: 2.7777778 | K7: 2.0833333 | L7: 2.3611111
A8: J007 | B8: 0 | C8: 11 | D8: 2.5 | E8: 0.55555556 | F8: 0.41666667 | G8: 0.41666667 | H8: 0.41666667 | I8: 1.1111111 | J8: 0.55555556 | K8: 0.55555556 | L8: 0.69444444
A9: J008 | B9: 1 | C9: 11 | D9: 10.416667 | E9: 3.3333333 | F9: 1.3888889 | G9: 1.6666667 | H9: 1.25 | I9: 0.55555556 | J9: 0.97222222 | K9: 2.3611111 | L9: 1.1111111
A10: J009 | B10: 1 | C10: 1 | D10: 7.5 | E10: 4.7222222 | F10: 5 | G10: 2.6388889 | H10: 3.3333333 | I10: 3.4722222 | J10: 2.9166667 | K10: 3.0555556 | L10: 3.6111111
A11: J010 | B11: 0 | C11: 11 | D11: 2.6388889 | E11: 0.97222222 | F11: 0.83333333 | G11: 0.69444444 | H11: 2.3611111 | I11: 1.5277778 | J11: 1.1111111 | K11: 1.25 | L11: 0.83333333
A12: J011 | B12: 0 | C12: 1 | D12: 4.0277778 | E12: 1.5277778 | F12: 1.5277778 | G12: 1.5277778 | H12: 1.6666667 | I12: 1.3888889 | J12: 0.83333333 | K12: 1.1111111 | L12: 1.3888889
A13: J012 | B13: 1 | C13: 1 | D13: 7.0833333 | E13: 3.0555556 | F13: 1.8055556 | G13: 1.25 | H13: nan | I13: nan | J13: nan | K13: nan | L13: nan
A14: J013 | B14: 1 | C14: 11 | D14: 2.2222222 | E14: 1.1111111 | F14: 1.5277778 | G14: 0.97222222 | H14: 1.25 | I14: 0.13888889 | J14: 1.1111111 | K14: 0.83333333 | L14: 0.69444444
A15: J014 | B15: 0 | C15: 1 | D15: 4.3055556 | E15: 4.5833333 | F15: 5.6944444 | G15: 5.9722222 | H15: 4.5833333 | I15: 3.8888889 | J15: 5.9722222 | K15: 6.25 | L15: 2.7777778
A20: 4.3055556 | B20: 3.8888889 | D20: =AVERAGE(A20:A26) -> 4.8809524 | M20: 2.3611111 | N20: 2.5 | P20: =AVERAGE(M20:M26) -> 1.547619
A21: 3.1944444 | B21: 1.5277778 | D21: =STDEV(A20:A26) -> 3.7426442 | M21: 0.41666667 | N21: 1.1111111 | P21: =STDEV(M20:M26) -> 0.94685345
A22: 13.194444 | B22: 5 | D22: =AVERAGE(B20:B26) -> 5.3769841 | M22: 2.3611111 | N22: 3.6111111 | P22: =AVERAGE(N20:N23) -> 1.9791667
A23: 2.5 | B23: 10.416667 | D23: =STDEV(B20:B26) -> 3.1607668 | M23: 0.69444444 | N23: 0.69444444 | P23: =STDEV(N20:N23) -> 1.3339842
A24: 2.6388889 | B24: 7.5 | M24: 0.83333333
A25: 4.0277778 | B25: 7.0833333 | M25: 1.3888889
A26: 4.3055556 | B26: 2.2222222 | M26: 2.7777778

Sheet JOGGNGSpeed
A1: participants | B1: interGroup | C1: cwGroup | D1: sess1 | E1: sess2 | F1: sess3 | G1: sess4 | H1: sess5 | I1: sess6 | J1: sess7 | K1: sess8 | L1: sess9
A2: J001 | B2: 1 | C2: 1 | D2: 0.26113596 | E2: 0.26039072 | F2: 0.25973608 | G2: nan | H2: nan | I2: nan | J2: nan | K2: nan | L2: nan
A3: J002 | B3: 0 | C3: 1 | D3: 0.26346203 | E3: 0.2644068 | F3: 0.26487008 | G3: 0.26651736 | H3: 0.26877088 | I3: 0.27184017 | J3: 0.27566424 | K3: 0.2791548 | L3: 0.28237152
A4: J003 | B4: 1 | C4: 11 | D4: 0.1790867 | E4: 0.23360977 | F4: 0.25435204 | G4: 0.25606813 | H4: 0.25576537 | I4: 0.26076077 | J4: 0.25988954 | K4: 0.2608916 | L4: 0.25864174
A5: J004 | B5: 0 | C5: 11 | D5: 0.25578629 | E5: 0.25790681 | F5: 0.25931633 | G5: 0.25969389 | H5: 0.25894874 | I5: 0.25780733 | J5: 0.25670544 | K5: 0.25528375 | L5: 0.25381556
A6: J005 | B6: 1 | C6: 1 | D6: 0.28089127 | E6: 0.27906419 | F6: 0.27727858 | G6: 0.27555145 | H6: 0.27387328 | I6: 0.27215894 | J6: nan | K6: nan | L6: nan
A7: J006 | B7: 0 | C7: 1 | D7: 0.26454689 | E7: 0.26387743 | F7: 0.26317354 | G7: 0.26246756 | H7: 0.26193539 | I7: 0.2618583 | J7: 0.26172727 | K7: 0.26180184 | L7: 0.26171818
A8: J007 | B8: 0 | C8: 11 | D8: 0.2531963 | E8: 0.2529846 | F8: 0.26514356 | G8: 0.27766249 | H8: 0.29500929 | I8: 0.30336554 | J8: 0.31119362 | K8: 0.32030335 | L8: 0.32710938
A9: J008 | B9: 1 | C9: 11 | D9: 0.25595581 | E9: 0.25474389 | F9: 0.25352601 | G9: 0.2539409 | H9: 0.25478005 | I9: 0.25605578 | J9: 0.258223 | K9: 0.26069634 | L9: 0.26508129
A10: J009 | B10: 1 | C10: 1 | D10: 0.25590694 | E10: 0.25583239 | F10: 0.25653674 | G10: 0.25660162 | H10: 0.25793343 | I10: 0.25949651 | J10: 0.26067901 | K10: 0.26145753 | L10: 0.26231682
A11: J010 | B11: 0 | C11: 11 | D11: 0.2484634 | E11: 0.24839463 | F11: 0.24856535 | G11: 0.24890865 | H11: 0.2504095 | I11: 0.25216646 | J11: 0.25376482 | K11: 0.25549416 | L11: 0.25715894
A12: J011 | B12: 0 | C12: 1 | D12: 0.27107117 | E12: 0.26977969 | F12: 0.2688119 | G12: 0.26803552 | H12: 0.26724888 | I12: 0.26669514 | J12: 0.26623932 | K12: 0.26562738 | L12: 0.26533158
A13: J012 | B13: 1 | C13: 1 | D13: 0.25469623 | E13: 0.2558509 | F13: 0.25686284 | G13: 0.25722311 | H13: nan | I13: nan | J13: nan | K13: nan | L13: nan
A14: J013 | B14: 1 | C14: 11 | D14: 0.31659795 | E14: 0.30634668 | F14: 0.29706471 | G14: 0.28822543 | H14: 0.28107346 | I14: 0.27364512 | J14: 0.26688464 | K14: 0.26030523 | L14: 0.25403251
A15: J014 | B15: 0 | C15: 1 | D15: 0.26231407 | E15: 0.25995387 | F15: 0.25792793 | G15: 0.25654152 | H15: 0.25509633 | I15: 0.25322914 | J15: 0.25168259 | K15: 0.25009544 | L15: 0.24845323

Sheet Sheet2
A1: group analysis | C1: pos is slower on it
A2: group | B2: assessment | C2: steps | D2: VMCPM | E2: AATapa | F2: AATaps | G2: AATava | H2: AATavs | I2: 6MWT | J2: Grip (KG*N) | K2: WHOQOL | L2: AIAS | M2: PES
A3: 0 | B3: 1 | C3: =AVERAGEIFS(Main!N2:N43,Main!B2:B43,"=0",Main!D2:D43,"=1") -> 7727.8197 | D3: =AVERAGEIFS(Main!#REF!,Main!B2:B43,"=0",Main!D2:D43,"=1") -> #REF! | E3: =AVERAGEIFS(Main!S2:S43,Main!B2:B43,"=0",Main!D2:D43,"=1") -> 187.85922 | F3: =AVERAGEIFS(Main!T2:T43,Main!B2:B43,"=0",Main!D2:D43,"=1") -> 220.08977 | G3: =AVERAGEIFS(Main!U2:U43,Main!B2:B43,"=0",Main!D2:D43,"=1") -> 210.27379 | H3: =AVERAGEIFS(Main!V2:V43,Main!B2:B43,"=0",Main!D2:D43,"=1") -> 363.49237 | I3: =AVERAGEIFS(Main!AA2:AA43,Main!B2:B43,"=0",Main!D2:D43,"=1") -> 418.92857 | J3: =AVERAGEIFS(Main!AB2:AB43,Main!B2:B43,"=0",Main!D2:D43,"=1") -> 28.428571 | K3: =AVERAGEIFS(Main!X2:X43,Main!B2:B43,"=0",Main!D2:D43,"=1") -> 103.57143 | L3: =AVERAGEIFS(Main!Y2:Y43,Main!B2:B43,"=0",Main!D2:D43,"=1") -> 10.571429 | M3: =AVERAGEIFS(Main!W2:W43,Main!B2:B43,"=0",Main!D2:D43,"=1") -> 1.6428571
B4: 2 | C4: =AVERAGEIFS(Main!N2:N43,Main!B2:B43,"=0",Main!D2:D43,"=2") -> 8932.6862 | D4: =AVERAGEIFS(Main!#REF!,Main!B2:B43,"=0",Main!D2:D43,"=2") -> #REF! | E4: =AVERAGEIFS(Main!S2:S43,Main!B2:B43,"=0",Main!D2:D43,"=2") -> 187.40038 | F4: =AVERAGEIFS(Main!T2:T43,Main!B2:B43,"=0",Main!D2:D43,"=2") -> 239.79177 | G4: =AVERAGEIFS(Main!U2:U43,Main!B2:B43,"=0",Main!D2:D43,"=2") -> 37.794888 | H4: =AVERAGEIFS(Main!V2:V43,Main!B2:B43,"=0",Main!D2:D43,"=2") -> 74.974471 | I4: =AVERAGEIFS(Main!AA2:AA43,Main!B2:B43,"=0",Main!D2:D43,"=2") -> 439.28571 | J4: =AVERAGEIFS(Main!AB2:AB43,Main!B2:B43,"=0",Main!D2:D43,"=2") -> 29.142857 | K4: =AVERAGEIFS(Main!X2:X43,Main!B2:B43,"=0",Main!D2:D43,"=2") -> 104.14286 | L4: =AVERAGEIFS(Main!Y2:Y43,Main!B2:B43,"=0",Main!D2:D43,"=2") -> 10.857143 | M4: =AVERAGEIFS(Main!W2:W43,Main!B2:B43,"=0",Main!D2:D43,"=2") -> 1.7142857
B5: 3 | C5: =AVERAGEIFS(Main!N2:N43,Main!B2:B43,"=0",Main!D2:D43,"=3") -> 6209.0918 | D5: =AVERAGEIFS(Main!#REF!,Main!B2:B43,"=0",Main!D2:D43,"=3") -> #REF! | E5: =AVERAGEIFS(Main!S2:S43,Main!B2:B43,"=0",Main!D2:D43,"=3") -> 126.72639 | F5: =AVERAGEIFS(Main!T2:T43,Main!B2:B43,"=0",Main!D2:D43,"=3") -> 88.326401 | G5: =AVERAGEIFS(Main!U2:U43,Main!B2:B43,"=0",Main!D2:D43,"=3") -> 114.6218 | H5: =AVERAGEIFS(Main!V2:V43,Main!B2:B43,"=0",Main!D2:D43,"=3") -> 104.59524 | I5: =AVERAGEIFS(Main!AA2:AA43,Main!B2:B43,"=0",Main!D2:D43,"=3") -> 458.57143 | J5: =AVERAGEIFS(Main!AB2:AB43,Main!B2:B43,"=0",Main!D2:D43,"=3") -> 31.285714 | K5: =AVERAGEIFS(Main!X2:X43,Main!B2:B43,"=0",Main!D2:D43,"=3") -> 106 | L5: =AVERAGEIFS(Main!Y2:Y43,Main!B2:B43,"=0",Main!D2:D43,"=3") -> 11.571429 | M5: =AVERAGEIFS(Main!W2:W43,Main!B2:B43,"=0",Main!D2:D43,"=3") -> 1.6785714
A7: 1 | B7: 1 | C7: =AVERAGEIFS(Main!N2:N43,Main!B2:B43,"=1",Main!D2:D43,"=1") -> 4993.6131 | D7: =AVERAGEIFS(Main!#REF!,Main!B2:B43,"=1",Main!D2:D43,"=1") -> #REF! | E7: =AVERAGEIFS(Main!AG44:AG45,Main!B5:B45,"=1",Main!D5:D45,"=1") -> #VALUE! | F7: =AVERAGEIFS(Main!AH44:AH45,Main!B5:B45,"=1",Main!D5:D45,"=1") -> #VALUE! | G7: =AVERAGEIFS(Main!AI44:AI45,Main!B5:B45,"=1",Main!D5:D45,"=1") -> #VALUE! | H7: =AVERAGEIFS(Main!AJ44:AJ45,Main!B5:B45,"=1",Main!D5:D45,"=1") -> #VALUE! | I7: =AVERAGEIFS(Main!V5:V45,Main!B5:B45,"=1",Main!D5:D45,"=1") -> 145.42979 | J7: =AVERAGEIFS(Main!X5:X45,Main!B5:B45,"=1",Main!D5:D45,"=1") -> 102.33333 | K7: =AVERAGEIFS(Main!AK44:AK45,Main!B5:B45,"=1",Main!D5:D45,"=1") -> #VALUE! | L7: =AVERAGEIFS(Main!S5:S45,Main!B5:B45,"=1",Main!D5:D45,"=1") -> 44.40227 | M7: =AVERAGEIFS(Main!U5:U45,Main!B5:B45,"=1",Main!D5:D45,"=1") -> 195.25255
B8: 2 | C8: =AVERAGEIFS(Main!N2:N43,Main!B2:B43,"=1",Main!D2:D43,"=2") -> 5108.4209 | D8: =AVERAGEIFS(Main!#REF!,Main!B2:B43,"=1",Main!D2:D43,"=2") -> #REF! | E8: =AVERAGEIFS(Main!AG44:AG45,Main!B5:B45,"=1",Main!D5:D45,"=2") -> #VALUE! | F8: =AVERAGEIFS(Main!AH44:AH45,Main!B5:B45,"=1",Main!D5:D45,"=2") -> #VALUE! | G8: =AVERAGEIFS(Main!AI44:AI45,Main!B5:B45,"=1",Main!D5:D45,"=2") -> #VALUE! | H8: =AVERAGEIFS(Main!AJ44:AJ45,Main!B5:B45,"=1",Main!D5:D45,"=2") -> #VALUE! | I8: =AVERAGEIFS(Main!V5:V45,Main!B5:B45,"=1",Main!D5:D45,"=2") -> 12.541818 | J8: =AVERAGEIFS(Main!X5:X45,Main!B5:B45,"=1",Main!D5:D45,"=2") -> 104 | K8: =AVERAGEIFS(Main!AK44:AK45,Main!B5:B45,"=1",Main!D5:D45,"=2") -> #VALUE! | L8: =AVERAGEIFS(Main!S5:S45,Main!B5:B45,"=1",Main!D5:D45,"=2") -> 19.986369 | M8: =AVERAGEIFS(Main!U5:U45,Main!B5:B45,"=1",Main!D5:D45,"=2") -> 43.737168
B9: 3 | C9: =AVERAGEIFS(Main!N2:N43,Main!B2:B43,"=1",Main!D2:D43,"=3") -> 4854.7715 | D9: =AVERAGEIFS(Main!#REF!,Main!B2:B43,"=1",Main!D2:D43,"=3") -> #REF! | E9: =AVERAGEIFS(Main!AG44:AG45,Main!B5:B45,"=1",Main!D5:D45,"=3") -> #VALUE! | F9: =AVERAGEIFS(Main!AH44:AH45,Main!B5:B45,"=1",Main!D5:D45,"=3") -> #VALUE! | G9: =AVERAGEIFS(Main!AI44:AI45,Main!B5:B45,"=1",Main!D5:D45,"=3") -> #VALUE! | H9: =AVERAGEIFS(Main!AJ44:AJ45,Main!B5:B45,"=1",Main!D5:D45,"=3") -> #VALUE! | I9: =AVERAGEIFS(Main!V5:V45,Main!B5:B45,"=1",Main!D5:D45,"=3") -> 0.82099528 | J9: =AVERAGEIFS(Main!X5:X45,Main!B5:B45,"=1",Main!D5:D45,"=3") -> 102.66667 | K9: =AVERAGEIFS(Main!AK44:AK45,Main!B5:B45,"=1",Main!D5:D45,"=3") -> #VALUE! | L9: =AVERAGEIFS(Main!S5:S45,Main!B5:B45,"=1",Main!D5:D45,"=3") -> -138.8573 | M9: =AVERAGEIFS(Main!U5:U45,Main!B5:B45,"=0",Main!D5:D45,"=3") -> 114.6218

Sheet Sheet1
B1: change
A2: group | B2: steps | C2: VMCPM | D2: AATapa | E2: AATaps | F2: AATava | G2: AATavs | H2: 6MWT | I2: Grip (KG*N) | J2: WHOQOL | K2: AIAS | L2: PES
A3: 0 | B3: =Sheet2!C4-Sheet2!C3 -> 1204.8665 | C3: =Sheet2!D4-Sheet2!D3 -> #REF! | D3: =Sheet2!E4-Sheet2!E3 -> -0.45884421 | E3: =Sheet2!F4-Sheet2!F3 -> 19.701998 | F3: =Sheet2!G4-Sheet2!G3 -> -172.4789 | G3: =Sheet2!H4-Sheet2!H3 -> -288.5179 | H3: =Sheet2!I4-Sheet2!I3 -> 20.357143 | I3: =Sheet2!J4-Sheet2!J3 -> 0.71428571 | ... L3: =Sheet2!M4-Sheet2!M3 -> 0.071428571
A4: 1 | B4: =Sheet2!C8-Sheet2!C7 -> 114.80782 | C4: =Sheet2!D8-Sheet2!D7 -> #REF! | D4: =Sheet2!E8-Sheet2!E7 -> #VALUE! | E4: =Sheet2!F8-Sheet2!F7 -> #VALUE! | F4: =Sheet2!G8-Sheet2!G7 -> #VALUE! | G4: =Sheet2!H8-Sheet2!H7 -> #VALUE! | H4: =Sheet2!I8-Sheet2!I7 -> -132.88797 | I4: =Sheet2!J8-Sheet2!J7 -> 1.6666667 | ... L4: =Sheet2!M8-Sheet2!M7 -> -151.51538
B6: more steps in group 0 | C6: more counts in group 0 | D6: faster to approach activity in grou 1 | E6: faster to approach sedentary in group 0 | F6: faster to avoid active in group 0 | G6: faster to avoid sedentary group 0 | H6: greater walking in group 1 | I6: greater grip strength in group 1 | J6: greater QOL in group 1 | K6: greater want to be active in group 0 | L6: greater perception of wanting physical activity in group 1
